[ERROR] 2021-03-25 11:15:31,727 | /home/frappe/frappe-bench/apps/frappe/frappe/utils/scheduler.py:
Site: site1.local
Exception in Enqueue Events for Site site1.local
Traceback (most recent call last):
  File "/home/frappe/frappe-bench/env/lib/python3.6/site-packages/pymysql/connections.py", line 583, in connect
    **kwargs)
  File "/usr/lib/python3.6/socket.py", line 724, in create_connection
    raise err
  File "/usr/lib/python3.6/socket.py", line 713, in create_connection
    sock.connect(sa)
ConnectionRefusedError: [Errno 111] Connection refused

During handling of the above exception, another exception occurred:

Traceback (most recent call last):
  File "/home/frappe/frappe-bench/apps/frappe/frappe/utils/scheduler.py", line 81, in enqueue_events_for_site
    if is_scheduler_inactive():
  File "/home/frappe/frappe-bench/apps/frappe/frappe/utils/scheduler.py", line 228, in is_scheduler_inactive
    if is_scheduler_disabled():
  File "/home/frappe/frappe-bench/apps/frappe/frappe/utils/scheduler.py", line 237, in is_scheduler_disabled
    return not frappe.utils.cint(frappe.db.get_single_value("System Settings", "enable_scheduler"))
  File "/home/frappe/frappe-bench/apps/frappe/frappe/database/database.py", line 553, in get_single_value
    `tabSingles` where `doctype`=%s and `field`=%s""", (doctype, fieldname))
  File "/home/frappe/frappe-bench/apps/frappe/frappe/database/database.py", line 122, in sql
    self.connect()
  File "/home/frappe/frappe-bench/apps/frappe/frappe/database/database.py", line 75, in connect
    self._conn = self.get_connection()
  File "/home/frappe/frappe-bench/apps/frappe/frappe/database/mariadb/database.py", line 90, in get_connection
    local_infile = frappe.conf.local_infile)
  File "/home/frappe/frappe-bench/env/lib/python3.6/site-packages/pymysql/__init__.py", line 94, in Connect
    return Connection(*args, **kwargs)
  File "/home/frappe/frappe-bench/env/lib/python3.6/site-packages/pymysql/connections.py", line 325, in __init__
    self.connect()
  File "/home/frappe/frappe-bench/env/lib/python3.6/site-packages/pymysql/connections.py", line 630, in connect
    raise exc
pymysql.err.OperationalError: (2003, "Can't connect to MySQL server on 'localhost' ([Errno 111] Connection refused)")

[ERROR] 2021-03-25 11:16:31,881 | /home/frappe/frappe-bench/apps/frappe/frappe/utils/scheduler.py:
Site: site1.local
Exception in Enqueue Events for Site site1.local
Traceback (most recent call last):
  File "/home/frappe/frappe-bench/env/lib/python3.6/site-packages/pymysql/connections.py", line 583, in connect
    **kwargs)
  File "/usr/lib/python3.6/socket.py", line 724, in create_connection
    raise err
  File "/usr/lib/python3.6/socket.py", line 713, in create_connection
    sock.connect(sa)
ConnectionRefusedError: [Errno 111] Connection refused

During handling of the above exception, another exception occurred:

Traceback (most recent call last):
  File "/home/frappe/frappe-bench/apps/frappe/frappe/utils/scheduler.py", line 81, in enqueue_events_for_site
    if is_scheduler_inactive():
  File "/home/frappe/frappe-bench/apps/frappe/frappe/utils/scheduler.py", line 228, in is_scheduler_inactive
    if is_scheduler_disabled():
  File "/home/frappe/frappe-bench/apps/frappe/frappe/utils/scheduler.py", line 237, in is_scheduler_disabled
    return not frappe.utils.cint(frappe.db.get_single_value("System Settings", "enable_scheduler"))
  File "/home/frappe/frappe-bench/apps/frappe/frappe/database/database.py", line 553, in get_single_value
    `tabSingles` where `doctype`=%s and `field`=%s""", (doctype, fieldname))
  File "/home/frappe/frappe-bench/apps/frappe/frappe/database/database.py", line 122, in sql
    self.connect()
  File "/home/frappe/frappe-bench/apps/frappe/frappe/database/database.py", line 75, in connect
    self._conn = self.get_connection()
  File "/home/frappe/frappe-bench/apps/frappe/frappe/database/mariadb/database.py", line 90, in get_connection
    local_infile = frappe.conf.local_infile)
  File "/home/frappe/frappe-bench/env/lib/python3.6/site-packages/pymysql/__init__.py", line 94, in Connect
    return Connection(*args, **kwargs)
  File "/home/frappe/frappe-bench/env/lib/python3.6/site-packages/pymysql/connections.py", line 325, in __init__
    self.connect()
  File "/home/frappe/frappe-bench/env/lib/python3.6/site-packages/pymysql/connections.py", line 630, in connect
    raise exc
pymysql.err.OperationalError: (2003, "Can't connect to MySQL server on 'localhost' ([Errno 111] Connection refused)")

[ERROR] 2021-03-25 11:17:32,036 | /home/frappe/frappe-bench/apps/frappe/frappe/utils/scheduler.py:
Site: site1.local
Exception in Enqueue Events for Site site1.local
Traceback (most recent call last):
  File "/home/frappe/frappe-bench/env/lib/python3.6/site-packages/pymysql/connections.py", line 583, in connect
    **kwargs)
  File "/usr/lib/python3.6/socket.py", line 724, in create_connection
    raise err
  File "/usr/lib/python3.6/socket.py", line 713, in create_connection
    sock.connect(sa)
ConnectionRefusedError: [Errno 111] Connection refused

During handling of the above exception, another exception occurred:

Traceback (most recent call last):
  File "/home/frappe/frappe-bench/apps/frappe/frappe/utils/scheduler.py", line 81, in enqueue_events_for_site
    if is_scheduler_inactive():
  File "/home/frappe/frappe-bench/apps/frappe/frappe/utils/scheduler.py", line 228, in is_scheduler_inactive
    if is_scheduler_disabled():
  File "/home/frappe/frappe-bench/apps/frappe/frappe/utils/scheduler.py", line 237, in is_scheduler_disabled
    return not frappe.utils.cint(frappe.db.get_single_value("System Settings", "enable_scheduler"))
  File "/home/frappe/frappe-bench/apps/frappe/frappe/database/database.py", line 553, in get_single_value
    `tabSingles` where `doctype`=%s and `field`=%s""", (doctype, fieldname))
  File "/home/frappe/frappe-bench/apps/frappe/frappe/database/database.py", line 122, in sql
    self.connect()
  File "/home/frappe/frappe-bench/apps/frappe/frappe/database/database.py", line 75, in connect
    self._conn = self.get_connection()
  File "/home/frappe/frappe-bench/apps/frappe/frappe/database/mariadb/database.py", line 90, in get_connection
    local_infile = frappe.conf.local_infile)
  File "/home/frappe/frappe-bench/env/lib/python3.6/site-packages/pymysql/__init__.py", line 94, in Connect
    return Connection(*args, **kwargs)
  File "/home/frappe/frappe-bench/env/lib/python3.6/site-packages/pymysql/connections.py", line 325, in __init__
    self.connect()
  File "/home/frappe/frappe-bench/env/lib/python3.6/site-packages/pymysql/connections.py", line 630, in connect
    raise exc
pymysql.err.OperationalError: (2003, "Can't connect to MySQL server on 'localhost' ([Errno 111] Connection refused)")

[ERROR] 2021-03-25 11:18:32,258 | /home/frappe/frappe-bench/apps/frappe/frappe/utils/scheduler.py:
Site: site1.local
Exception in Enqueue Events for Site site1.local
Traceback (most recent call last):
  File "/home/frappe/frappe-bench/env/lib/python3.6/site-packages/pymysql/connections.py", line 583, in connect
    **kwargs)
  File "/usr/lib/python3.6/socket.py", line 724, in create_connection
    raise err
  File "/usr/lib/python3.6/socket.py", line 713, in create_connection
    sock.connect(sa)
ConnectionRefusedError: [Errno 111] Connection refused

During handling of the above exception, another exception occurred:

Traceback (most recent call last):
  File "/home/frappe/frappe-bench/apps/frappe/frappe/utils/scheduler.py", line 81, in enqueue_events_for_site
    if is_scheduler_inactive():
  File "/home/frappe/frappe-bench/apps/frappe/frappe/utils/scheduler.py", line 228, in is_scheduler_inactive
    if is_scheduler_disabled():
  File "/home/frappe/frappe-bench/apps/frappe/frappe/utils/scheduler.py", line 237, in is_scheduler_disabled
    return not frappe.utils.cint(frappe.db.get_single_value("System Settings", "enable_scheduler"))
  File "/home/frappe/frappe-bench/apps/frappe/frappe/database/database.py", line 553, in get_single_value
    `tabSingles` where `doctype`=%s and `field`=%s""", (doctype, fieldname))
  File "/home/frappe/frappe-bench/apps/frappe/frappe/database/database.py", line 122, in sql
    self.connect()
  File "/home/frappe/frappe-bench/apps/frappe/frappe/database/database.py", line 75, in connect
    self._conn = self.get_connection()
  File "/home/frappe/frappe-bench/apps/frappe/frappe/database/mariadb/database.py", line 90, in get_connection
    local_infile = frappe.conf.local_infile)
  File "/home/frappe/frappe-bench/env/lib/python3.6/site-packages/pymysql/__init__.py", line 94, in Connect
    return Connection(*args, **kwargs)
  File "/home/frappe/frappe-bench/env/lib/python3.6/site-packages/pymysql/connections.py", line 325, in __init__
    self.connect()
  File "/home/frappe/frappe-bench/env/lib/python3.6/site-packages/pymysql/connections.py", line 630, in connect
    raise exc
pymysql.err.OperationalError: (2003, "Can't connect to MySQL server on 'localhost' ([Errno 111] Connection refused)")

[ERROR] 2021-03-25 11:18:58,850 | /home/frappe/frappe-bench/apps/frappe/frappe/app.py:
Site: site1.local
Request Error
Traceback (most recent call last):
  File "/home/frappe/frappe-bench/env/lib/python3.6/site-packages/pymysql/connections.py", line 583, in connect
    **kwargs)
  File "/usr/lib/python3.6/socket.py", line 724, in create_connection
    raise err
  File "/usr/lib/python3.6/socket.py", line 713, in create_connection
    sock.connect(sa)
ConnectionRefusedError: [Errno 111] Connection refused

During handling of the above exception, another exception occurred:

Traceback (most recent call last):
  File "/home/frappe/frappe-bench/apps/frappe/frappe/app.py", line 54, in application
    init_request(request)
  File "/home/frappe/frappe-bench/apps/frappe/frappe/app.py", line 126, in init_request
    frappe.local.http_request = frappe.auth.HTTPRequest()
  File "/home/frappe/frappe-bench/apps/frappe/frappe/auth.py", line 42, in __init__
    self.set_lang()
  File "/home/frappe/frappe-bench/apps/frappe/frappe/auth.py", line 86, in set_lang
    frappe.local.lang = guess_language()
  File "/home/frappe/frappe-bench/apps/frappe/frappe/translate.py", line 29, in guess_language
    lang_list = get_all_languages() or []
  File "/home/frappe/frappe-bench/apps/frappe/frappe/translate.py", line 85, in get_all_languages
    return frappe.cache().get_value('languages', _get)
  File "/home/frappe/frappe-bench/apps/frappe/frappe/utils/redis_wrapper.py", line 79, in get_value
    val = generator()
  File "/home/frappe/frappe-bench/apps/frappe/frappe/translate.py", line 84, in _get
    return frappe.db.sql_list('select name from tabLanguage')
  File "/home/frappe/frappe-bench/apps/frappe/frappe/database/database.py", line 236, in sql_list
    return [r[0] for r in self.sql(query, values, debug=debug)]
  File "/home/frappe/frappe-bench/apps/frappe/frappe/database/database.py", line 122, in sql
    self.connect()
  File "/home/frappe/frappe-bench/apps/frappe/frappe/database/database.py", line 75, in connect
    self._conn = self.get_connection()
  File "/home/frappe/frappe-bench/apps/frappe/frappe/database/mariadb/database.py", line 90, in get_connection
    local_infile = frappe.conf.local_infile)
  File "/home/frappe/frappe-bench/env/lib/python3.6/site-packages/pymysql/__init__.py", line 94, in Connect
    return Connection(*args, **kwargs)
  File "/home/frappe/frappe-bench/env/lib/python3.6/site-packages/pymysql/connections.py", line 325, in __init__
    self.connect()
  File "/home/frappe/frappe-bench/env/lib/python3.6/site-packages/pymysql/connections.py", line 630, in connect
    raise exc
pymysql.err.OperationalError: (2003, "Can't connect to MySQL server on 'localhost' ([Errno 111] Connection refused)")
[ERROR] 2021-03-25 11:18:58,926 | /home/frappe/frappe-bench/apps/frappe/frappe/utils/error.py:
New Exception collected with id: 2021-03-25 11:18:58.855772-10.0.2.2-27c
[ERROR] 2021-03-25 11:18:59,755 | /home/frappe/frappe-bench/apps/frappe/frappe/app.py:
Site: site1.local
Request Error
Traceback (most recent call last):
  File "/home/frappe/frappe-bench/env/lib/python3.6/site-packages/pymysql/connections.py", line 583, in connect
    **kwargs)
  File "/usr/lib/python3.6/socket.py", line 724, in create_connection
    raise err
  File "/usr/lib/python3.6/socket.py", line 713, in create_connection
    sock.connect(sa)
ConnectionRefusedError: [Errno 111] Connection refused

During handling of the above exception, another exception occurred:

Traceback (most recent call last):
  File "/home/frappe/frappe-bench/apps/frappe/frappe/app.py", line 54, in application
    init_request(request)
  File "/home/frappe/frappe-bench/apps/frappe/frappe/app.py", line 126, in init_request
    frappe.local.http_request = frappe.auth.HTTPRequest()
  File "/home/frappe/frappe-bench/apps/frappe/frappe/auth.py", line 42, in __init__
    self.set_lang()
  File "/home/frappe/frappe-bench/apps/frappe/frappe/auth.py", line 86, in set_lang
    frappe.local.lang = guess_language()
  File "/home/frappe/frappe-bench/apps/frappe/frappe/translate.py", line 29, in guess_language
    lang_list = get_all_languages() or []
  File "/home/frappe/frappe-bench/apps/frappe/frappe/translate.py", line 85, in get_all_languages
    return frappe.cache().get_value('languages', _get)
  File "/home/frappe/frappe-bench/apps/frappe/frappe/utils/redis_wrapper.py", line 79, in get_value
    val = generator()
  File "/home/frappe/frappe-bench/apps/frappe/frappe/translate.py", line 84, in _get
    return frappe.db.sql_list('select name from tabLanguage')
  File "/home/frappe/frappe-bench/apps/frappe/frappe/database/database.py", line 236, in sql_list
    return [r[0] for r in self.sql(query, values, debug=debug)]
  File "/home/frappe/frappe-bench/apps/frappe/frappe/database/database.py", line 122, in sql
    self.connect()
  File "/home/frappe/frappe-bench/apps/frappe/frappe/database/database.py", line 75, in connect
    self._conn = self.get_connection()
  File "/home/frappe/frappe-bench/apps/frappe/frappe/database/mariadb/database.py", line 90, in get_connection
    local_infile = frappe.conf.local_infile)
  File "/home/frappe/frappe-bench/env/lib/python3.6/site-packages/pymysql/__init__.py", line 94, in Connect
    return Connection(*args, **kwargs)
  File "/home/frappe/frappe-bench/env/lib/python3.6/site-packages/pymysql/connections.py", line 325, in __init__
    self.connect()
  File "/home/frappe/frappe-bench/env/lib/python3.6/site-packages/pymysql/connections.py", line 630, in connect
    raise exc
pymysql.err.OperationalError: (2003, "Can't connect to MySQL server on 'localhost' ([Errno 111] Connection refused)")
[ERROR] 2021-03-25 11:18:59,808 | /home/frappe/frappe-bench/apps/frappe/frappe/utils/error.py:
New Exception collected with id: 2021-03-25 11:18:59.755549-10.0.2.2-eb8
[ERROR] 2021-03-25 11:19:32,457 | /home/frappe/frappe-bench/apps/frappe/frappe/utils/scheduler.py:
Site: site1.local
Exception in Enqueue Events for Site site1.local
Traceback (most recent call last):
  File "/home/frappe/frappe-bench/env/lib/python3.6/site-packages/pymysql/connections.py", line 583, in connect
    **kwargs)
  File "/usr/lib/python3.6/socket.py", line 724, in create_connection
    raise err
  File "/usr/lib/python3.6/socket.py", line 713, in create_connection
    sock.connect(sa)
ConnectionRefusedError: [Errno 111] Connection refused

During handling of the above exception, another exception occurred:

Traceback (most recent call last):
  File "/home/frappe/frappe-bench/apps/frappe/frappe/utils/scheduler.py", line 81, in enqueue_events_for_site
    if is_scheduler_inactive():
  File "/home/frappe/frappe-bench/apps/frappe/frappe/utils/scheduler.py", line 228, in is_scheduler_inactive
    if is_scheduler_disabled():
  File "/home/frappe/frappe-bench/apps/frappe/frappe/utils/scheduler.py", line 237, in is_scheduler_disabled
    return not frappe.utils.cint(frappe.db.get_single_value("System Settings", "enable_scheduler"))
  File "/home/frappe/frappe-bench/apps/frappe/frappe/database/database.py", line 553, in get_single_value
    `tabSingles` where `doctype`=%s and `field`=%s""", (doctype, fieldname))
  File "/home/frappe/frappe-bench/apps/frappe/frappe/database/database.py", line 122, in sql
    self.connect()
  File "/home/frappe/frappe-bench/apps/frappe/frappe/database/database.py", line 75, in connect
    self._conn = self.get_connection()
  File "/home/frappe/frappe-bench/apps/frappe/frappe/database/mariadb/database.py", line 90, in get_connection
    local_infile = frappe.conf.local_infile)
  File "/home/frappe/frappe-bench/env/lib/python3.6/site-packages/pymysql/__init__.py", line 94, in Connect
    return Connection(*args, **kwargs)
  File "/home/frappe/frappe-bench/env/lib/python3.6/site-packages/pymysql/connections.py", line 325, in __init__
    self.connect()
  File "/home/frappe/frappe-bench/env/lib/python3.6/site-packages/pymysql/connections.py", line 630, in connect
    raise exc
pymysql.err.OperationalError: (2003, "Can't connect to MySQL server on 'localhost' ([Errno 111] Connection refused)")

[ERROR] 2021-03-25 11:20:32,631 | /home/frappe/frappe-bench/apps/frappe/frappe/utils/scheduler.py:
Site: site1.local
Exception in Enqueue Events for Site site1.local
Traceback (most recent call last):
  File "/home/frappe/frappe-bench/env/lib/python3.6/site-packages/pymysql/connections.py", line 583, in connect
    **kwargs)
  File "/usr/lib/python3.6/socket.py", line 724, in create_connection
    raise err
  File "/usr/lib/python3.6/socket.py", line 713, in create_connection
    sock.connect(sa)
ConnectionRefusedError: [Errno 111] Connection refused

During handling of the above exception, another exception occurred:

Traceback (most recent call last):
  File "/home/frappe/frappe-bench/apps/frappe/frappe/utils/scheduler.py", line 81, in enqueue_events_for_site
    if is_scheduler_inactive():
  File "/home/frappe/frappe-bench/apps/frappe/frappe/utils/scheduler.py", line 228, in is_scheduler_inactive
    if is_scheduler_disabled():
  File "/home/frappe/frappe-bench/apps/frappe/frappe/utils/scheduler.py", line 237, in is_scheduler_disabled
    return not frappe.utils.cint(frappe.db.get_single_value("System Settings", "enable_scheduler"))
  File "/home/frappe/frappe-bench/apps/frappe/frappe/database/database.py", line 553, in get_single_value
    `tabSingles` where `doctype`=%s and `field`=%s""", (doctype, fieldname))
  File "/home/frappe/frappe-bench/apps/frappe/frappe/database/database.py", line 122, in sql
    self.connect()
  File "/home/frappe/frappe-bench/apps/frappe/frappe/database/database.py", line 75, in connect
    self._conn = self.get_connection()
  File "/home/frappe/frappe-bench/apps/frappe/frappe/database/mariadb/database.py", line 90, in get_connection
    local_infile = frappe.conf.local_infile)
  File "/home/frappe/frappe-bench/env/lib/python3.6/site-packages/pymysql/__init__.py", line 94, in Connect
    return Connection(*args, **kwargs)
  File "/home/frappe/frappe-bench/env/lib/python3.6/site-packages/pymysql/connections.py", line 325, in __init__
    self.connect()
  File "/home/frappe/frappe-bench/env/lib/python3.6/site-packages/pymysql/connections.py", line 630, in connect
    raise exc
pymysql.err.OperationalError: (2003, "Can't connect to MySQL server on 'localhost' ([Errno 111] Connection refused)")

[ERROR] 2021-03-25 11:21:32,850 | /home/frappe/frappe-bench/apps/frappe/frappe/utils/scheduler.py:
Site: site1.local
Exception in Enqueue Events for Site site1.local
Traceback (most recent call last):
  File "/home/frappe/frappe-bench/env/lib/python3.6/site-packages/pymysql/connections.py", line 583, in connect
    **kwargs)
  File "/usr/lib/python3.6/socket.py", line 724, in create_connection
    raise err
  File "/usr/lib/python3.6/socket.py", line 713, in create_connection
    sock.connect(sa)
ConnectionRefusedError: [Errno 111] Connection refused

During handling of the above exception, another exception occurred:

Traceback (most recent call last):
  File "/home/frappe/frappe-bench/apps/frappe/frappe/utils/scheduler.py", line 81, in enqueue_events_for_site
    if is_scheduler_inactive():
  File "/home/frappe/frappe-bench/apps/frappe/frappe/utils/scheduler.py", line 228, in is_scheduler_inactive
    if is_scheduler_disabled():
  File "/home/frappe/frappe-bench/apps/frappe/frappe/utils/scheduler.py", line 237, in is_scheduler_disabled
    return not frappe.utils.cint(frappe.db.get_single_value("System Settings", "enable_scheduler"))
  File "/home/frappe/frappe-bench/apps/frappe/frappe/database/database.py", line 553, in get_single_value
    `tabSingles` where `doctype`=%s and `field`=%s""", (doctype, fieldname))
  File "/home/frappe/frappe-bench/apps/frappe/frappe/database/database.py", line 122, in sql
    self.connect()
  File "/home/frappe/frappe-bench/apps/frappe/frappe/database/database.py", line 75, in connect
    self._conn = self.get_connection()
  File "/home/frappe/frappe-bench/apps/frappe/frappe/database/mariadb/database.py", line 90, in get_connection
    local_infile = frappe.conf.local_infile)
  File "/home/frappe/frappe-bench/env/lib/python3.6/site-packages/pymysql/__init__.py", line 94, in Connect
    return Connection(*args, **kwargs)
  File "/home/frappe/frappe-bench/env/lib/python3.6/site-packages/pymysql/connections.py", line 325, in __init__
    self.connect()
  File "/home/frappe/frappe-bench/env/lib/python3.6/site-packages/pymysql/connections.py", line 630, in connect
    raise exc
pymysql.err.OperationalError: (2003, "Can't connect to MySQL server on 'localhost' ([Errno 111] Connection refused)")

[ERROR] 2021-03-25 11:22:33,042 | /home/frappe/frappe-bench/apps/frappe/frappe/utils/scheduler.py:
Site: site1.local
Exception in Enqueue Events for Site site1.local
Traceback (most recent call last):
  File "/home/frappe/frappe-bench/env/lib/python3.6/site-packages/pymysql/connections.py", line 583, in connect
    **kwargs)
  File "/usr/lib/python3.6/socket.py", line 724, in create_connection
    raise err
  File "/usr/lib/python3.6/socket.py", line 713, in create_connection
    sock.connect(sa)
ConnectionRefusedError: [Errno 111] Connection refused

During handling of the above exception, another exception occurred:

Traceback (most recent call last):
  File "/home/frappe/frappe-bench/apps/frappe/frappe/utils/scheduler.py", line 81, in enqueue_events_for_site
    if is_scheduler_inactive():
  File "/home/frappe/frappe-bench/apps/frappe/frappe/utils/scheduler.py", line 228, in is_scheduler_inactive
    if is_scheduler_disabled():
  File "/home/frappe/frappe-bench/apps/frappe/frappe/utils/scheduler.py", line 237, in is_scheduler_disabled
    return not frappe.utils.cint(frappe.db.get_single_value("System Settings", "enable_scheduler"))
  File "/home/frappe/frappe-bench/apps/frappe/frappe/database/database.py", line 553, in get_single_value
    `tabSingles` where `doctype`=%s and `field`=%s""", (doctype, fieldname))
  File "/home/frappe/frappe-bench/apps/frappe/frappe/database/database.py", line 122, in sql
    self.connect()
  File "/home/frappe/frappe-bench/apps/frappe/frappe/database/database.py", line 75, in connect
    self._conn = self.get_connection()
  File "/home/frappe/frappe-bench/apps/frappe/frappe/database/mariadb/database.py", line 90, in get_connection
    local_infile = frappe.conf.local_infile)
  File "/home/frappe/frappe-bench/env/lib/python3.6/site-packages/pymysql/__init__.py", line 94, in Connect
    return Connection(*args, **kwargs)
  File "/home/frappe/frappe-bench/env/lib/python3.6/site-packages/pymysql/connections.py", line 325, in __init__
    self.connect()
  File "/home/frappe/frappe-bench/env/lib/python3.6/site-packages/pymysql/connections.py", line 630, in connect
    raise exc
pymysql.err.OperationalError: (2003, "Can't connect to MySQL server on 'localhost' ([Errno 111] Connection refused)")

[ERROR] 2021-03-25 11:23:33,258 | /home/frappe/frappe-bench/apps/frappe/frappe/utils/scheduler.py:
Site: site1.local
Exception in Enqueue Events for Site site1.local
Traceback (most recent call last):
  File "/home/frappe/frappe-bench/env/lib/python3.6/site-packages/pymysql/connections.py", line 583, in connect
    **kwargs)
  File "/usr/lib/python3.6/socket.py", line 724, in create_connection
    raise err
  File "/usr/lib/python3.6/socket.py", line 713, in create_connection
    sock.connect(sa)
ConnectionRefusedError: [Errno 111] Connection refused

During handling of the above exception, another exception occurred:

Traceback (most recent call last):
  File "/home/frappe/frappe-bench/apps/frappe/frappe/utils/scheduler.py", line 81, in enqueue_events_for_site
    if is_scheduler_inactive():
  File "/home/frappe/frappe-bench/apps/frappe/frappe/utils/scheduler.py", line 228, in is_scheduler_inactive
    if is_scheduler_disabled():
  File "/home/frappe/frappe-bench/apps/frappe/frappe/utils/scheduler.py", line 237, in is_scheduler_disabled
    return not frappe.utils.cint(frappe.db.get_single_value("System Settings", "enable_scheduler"))
  File "/home/frappe/frappe-bench/apps/frappe/frappe/database/database.py", line 553, in get_single_value
    `tabSingles` where `doctype`=%s and `field`=%s""", (doctype, fieldname))
  File "/home/frappe/frappe-bench/apps/frappe/frappe/database/database.py", line 122, in sql
    self.connect()
  File "/home/frappe/frappe-bench/apps/frappe/frappe/database/database.py", line 75, in connect
    self._conn = self.get_connection()
  File "/home/frappe/frappe-bench/apps/frappe/frappe/database/mariadb/database.py", line 90, in get_connection
    local_infile = frappe.conf.local_infile)
  File "/home/frappe/frappe-bench/env/lib/python3.6/site-packages/pymysql/__init__.py", line 94, in Connect
    return Connection(*args, **kwargs)
  File "/home/frappe/frappe-bench/env/lib/python3.6/site-packages/pymysql/connections.py", line 325, in __init__
    self.connect()
  File "/home/frappe/frappe-bench/env/lib/python3.6/site-packages/pymysql/connections.py", line 630, in connect
    raise exc
pymysql.err.OperationalError: (2003, "Can't connect to MySQL server on 'localhost' ([Errno 111] Connection refused)")

[ERROR] 2021-03-25 11:24:33,452 | /home/frappe/frappe-bench/apps/frappe/frappe/utils/scheduler.py:
Site: site1.local
Exception in Enqueue Events for Site site1.local
Traceback (most recent call last):
  File "/home/frappe/frappe-bench/env/lib/python3.6/site-packages/pymysql/connections.py", line 583, in connect
    **kwargs)
  File "/usr/lib/python3.6/socket.py", line 724, in create_connection
    raise err
  File "/usr/lib/python3.6/socket.py", line 713, in create_connection
    sock.connect(sa)
ConnectionRefusedError: [Errno 111] Connection refused

During handling of the above exception, another exception occurred:

Traceback (most recent call last):
  File "/home/frappe/frappe-bench/apps/frappe/frappe/utils/scheduler.py", line 81, in enqueue_events_for_site
    if is_scheduler_inactive():
  File "/home/frappe/frappe-bench/apps/frappe/frappe/utils/scheduler.py", line 228, in is_scheduler_inactive
    if is_scheduler_disabled():
  File "/home/frappe/frappe-bench/apps/frappe/frappe/utils/scheduler.py", line 237, in is_scheduler_disabled
    return not frappe.utils.cint(frappe.db.get_single_value("System Settings", "enable_scheduler"))
  File "/home/frappe/frappe-bench/apps/frappe/frappe/database/database.py", line 553, in get_single_value
    `tabSingles` where `doctype`=%s and `field`=%s""", (doctype, fieldname))
  File "/home/frappe/frappe-bench/apps/frappe/frappe/database/database.py", line 122, in sql
    self.connect()
  File "/home/frappe/frappe-bench/apps/frappe/frappe/database/database.py", line 75, in connect
    self._conn = self.get_connection()
  File "/home/frappe/frappe-bench/apps/frappe/frappe/database/mariadb/database.py", line 90, in get_connection
    local_infile = frappe.conf.local_infile)
  File "/home/frappe/frappe-bench/env/lib/python3.6/site-packages/pymysql/__init__.py", line 94, in Connect
    return Connection(*args, **kwargs)
  File "/home/frappe/frappe-bench/env/lib/python3.6/site-packages/pymysql/connections.py", line 325, in __init__
    self.connect()
  File "/home/frappe/frappe-bench/env/lib/python3.6/site-packages/pymysql/connections.py", line 630, in connect
    raise exc
pymysql.err.OperationalError: (2003, "Can't connect to MySQL server on 'localhost' ([Errno 111] Connection refused)")

[ERROR] 2021-03-25 11:25:33,645 | /home/frappe/frappe-bench/apps/frappe/frappe/utils/scheduler.py:
Site: site1.local
Exception in Enqueue Events for Site site1.local
Traceback (most recent call last):
  File "/home/frappe/frappe-bench/env/lib/python3.6/site-packages/pymysql/connections.py", line 583, in connect
    **kwargs)
  File "/usr/lib/python3.6/socket.py", line 724, in create_connection
    raise err
  File "/usr/lib/python3.6/socket.py", line 713, in create_connection
    sock.connect(sa)
ConnectionRefusedError: [Errno 111] Connection refused

During handling of the above exception, another exception occurred:

Traceback (most recent call last):
  File "/home/frappe/frappe-bench/apps/frappe/frappe/utils/scheduler.py", line 81, in enqueue_events_for_site
    if is_scheduler_inactive():
  File "/home/frappe/frappe-bench/apps/frappe/frappe/utils/scheduler.py", line 228, in is_scheduler_inactive
    if is_scheduler_disabled():
  File "/home/frappe/frappe-bench/apps/frappe/frappe/utils/scheduler.py", line 237, in is_scheduler_disabled
    return not frappe.utils.cint(frappe.db.get_single_value("System Settings", "enable_scheduler"))
  File "/home/frappe/frappe-bench/apps/frappe/frappe/database/database.py", line 553, in get_single_value
    `tabSingles` where `doctype`=%s and `field`=%s""", (doctype, fieldname))
  File "/home/frappe/frappe-bench/apps/frappe/frappe/database/database.py", line 122, in sql
    self.connect()
  File "/home/frappe/frappe-bench/apps/frappe/frappe/database/database.py", line 75, in connect
    self._conn = self.get_connection()
  File "/home/frappe/frappe-bench/apps/frappe/frappe/database/mariadb/database.py", line 90, in get_connection
    local_infile = frappe.conf.local_infile)
  File "/home/frappe/frappe-bench/env/lib/python3.6/site-packages/pymysql/__init__.py", line 94, in Connect
    return Connection(*args, **kwargs)
  File "/home/frappe/frappe-bench/env/lib/python3.6/site-packages/pymysql/connections.py", line 325, in __init__
    self.connect()
  File "/home/frappe/frappe-bench/env/lib/python3.6/site-packages/pymysql/connections.py", line 630, in connect
    raise exc
pymysql.err.OperationalError: (2003, "Can't connect to MySQL server on 'localhost' ([Errno 111] Connection refused)")

[ERROR] 2021-03-25 11:26:33,962 | /home/frappe/frappe-bench/apps/frappe/frappe/utils/scheduler.py:
Site: site1.local
Exception in Enqueue Events for Site site1.local
Traceback (most recent call last):
  File "/home/frappe/frappe-bench/env/lib/python3.6/site-packages/pymysql/connections.py", line 583, in connect
    **kwargs)
  File "/usr/lib/python3.6/socket.py", line 724, in create_connection
    raise err
  File "/usr/lib/python3.6/socket.py", line 713, in create_connection
    sock.connect(sa)
ConnectionRefusedError: [Errno 111] Connection refused

During handling of the above exception, another exception occurred:

Traceback (most recent call last):
  File "/home/frappe/frappe-bench/apps/frappe/frappe/utils/scheduler.py", line 81, in enqueue_events_for_site
    if is_scheduler_inactive():
  File "/home/frappe/frappe-bench/apps/frappe/frappe/utils/scheduler.py", line 228, in is_scheduler_inactive
    if is_scheduler_disabled():
  File "/home/frappe/frappe-bench/apps/frappe/frappe/utils/scheduler.py", line 237, in is_scheduler_disabled
    return not frappe.utils.cint(frappe.db.get_single_value("System Settings", "enable_scheduler"))
  File "/home/frappe/frappe-bench/apps/frappe/frappe/database/database.py", line 553, in get_single_value
    `tabSingles` where `doctype`=%s and `field`=%s""", (doctype, fieldname))
  File "/home/frappe/frappe-bench/apps/frappe/frappe/database/database.py", line 122, in sql
    self.connect()
  File "/home/frappe/frappe-bench/apps/frappe/frappe/database/database.py", line 75, in connect
    self._conn = self.get_connection()
  File "/home/frappe/frappe-bench/apps/frappe/frappe/database/mariadb/database.py", line 90, in get_connection
    local_infile = frappe.conf.local_infile)
  File "/home/frappe/frappe-bench/env/lib/python3.6/site-packages/pymysql/__init__.py", line 94, in Connect
    return Connection(*args, **kwargs)
  File "/home/frappe/frappe-bench/env/lib/python3.6/site-packages/pymysql/connections.py", line 325, in __init__
    self.connect()
  File "/home/frappe/frappe-bench/env/lib/python3.6/site-packages/pymysql/connections.py", line 630, in connect
    raise exc
pymysql.err.OperationalError: (2003, "Can't connect to MySQL server on 'localhost' ([Errno 111] Connection refused)")

[ERROR] 2021-03-25 11:27:34,133 | /home/frappe/frappe-bench/apps/frappe/frappe/utils/scheduler.py:
Site: site1.local
Exception in Enqueue Events for Site site1.local
Traceback (most recent call last):
  File "/home/frappe/frappe-bench/env/lib/python3.6/site-packages/pymysql/connections.py", line 583, in connect
    **kwargs)
  File "/usr/lib/python3.6/socket.py", line 724, in create_connection
    raise err
  File "/usr/lib/python3.6/socket.py", line 713, in create_connection
    sock.connect(sa)
ConnectionRefusedError: [Errno 111] Connection refused

During handling of the above exception, another exception occurred:

Traceback (most recent call last):
  File "/home/frappe/frappe-bench/apps/frappe/frappe/utils/scheduler.py", line 81, in enqueue_events_for_site
    if is_scheduler_inactive():
  File "/home/frappe/frappe-bench/apps/frappe/frappe/utils/scheduler.py", line 228, in is_scheduler_inactive
    if is_scheduler_disabled():
  File "/home/frappe/frappe-bench/apps/frappe/frappe/utils/scheduler.py", line 237, in is_scheduler_disabled
    return not frappe.utils.cint(frappe.db.get_single_value("System Settings", "enable_scheduler"))
  File "/home/frappe/frappe-bench/apps/frappe/frappe/database/database.py", line 553, in get_single_value
    `tabSingles` where `doctype`=%s and `field`=%s""", (doctype, fieldname))
  File "/home/frappe/frappe-bench/apps/frappe/frappe/database/database.py", line 122, in sql
    self.connect()
  File "/home/frappe/frappe-bench/apps/frappe/frappe/database/database.py", line 75, in connect
    self._conn = self.get_connection()
  File "/home/frappe/frappe-bench/apps/frappe/frappe/database/mariadb/database.py", line 90, in get_connection
    local_infile = frappe.conf.local_infile)
  File "/home/frappe/frappe-bench/env/lib/python3.6/site-packages/pymysql/__init__.py", line 94, in Connect
    return Connection(*args, **kwargs)
  File "/home/frappe/frappe-bench/env/lib/python3.6/site-packages/pymysql/connections.py", line 325, in __init__
    self.connect()
  File "/home/frappe/frappe-bench/env/lib/python3.6/site-packages/pymysql/connections.py", line 630, in connect
    raise exc
pymysql.err.OperationalError: (2003, "Can't connect to MySQL server on 'localhost' ([Errno 111] Connection refused)")

[ERROR] 2021-03-25 11:28:34,479 | /home/frappe/frappe-bench/apps/frappe/frappe/utils/scheduler.py:
Site: site1.local
Exception in Enqueue Events for Site site1.local
Traceback (most recent call last):
  File "/home/frappe/frappe-bench/env/lib/python3.6/site-packages/pymysql/connections.py", line 583, in connect
    **kwargs)
  File "/usr/lib/python3.6/socket.py", line 724, in create_connection
    raise err
  File "/usr/lib/python3.6/socket.py", line 713, in create_connection
    sock.connect(sa)
ConnectionRefusedError: [Errno 111] Connection refused

During handling of the above exception, another exception occurred:

Traceback (most recent call last):
  File "/home/frappe/frappe-bench/apps/frappe/frappe/utils/scheduler.py", line 81, in enqueue_events_for_site
    if is_scheduler_inactive():
  File "/home/frappe/frappe-bench/apps/frappe/frappe/utils/scheduler.py", line 228, in is_scheduler_inactive
    if is_scheduler_disabled():
  File "/home/frappe/frappe-bench/apps/frappe/frappe/utils/scheduler.py", line 237, in is_scheduler_disabled
    return not frappe.utils.cint(frappe.db.get_single_value("System Settings", "enable_scheduler"))
  File "/home/frappe/frappe-bench/apps/frappe/frappe/database/database.py", line 553, in get_single_value
    `tabSingles` where `doctype`=%s and `field`=%s""", (doctype, fieldname))
  File "/home/frappe/frappe-bench/apps/frappe/frappe/database/database.py", line 122, in sql
    self.connect()
  File "/home/frappe/frappe-bench/apps/frappe/frappe/database/database.py", line 75, in connect
    self._conn = self.get_connection()
  File "/home/frappe/frappe-bench/apps/frappe/frappe/database/mariadb/database.py", line 90, in get_connection
    local_infile = frappe.conf.local_infile)
  File "/home/frappe/frappe-bench/env/lib/python3.6/site-packages/pymysql/__init__.py", line 94, in Connect
    return Connection(*args, **kwargs)
  File "/home/frappe/frappe-bench/env/lib/python3.6/site-packages/pymysql/connections.py", line 325, in __init__
    self.connect()
  File "/home/frappe/frappe-bench/env/lib/python3.6/site-packages/pymysql/connections.py", line 630, in connect
    raise exc
pymysql.err.OperationalError: (2003, "Can't connect to MySQL server on 'localhost' ([Errno 111] Connection refused)")

[ERROR] 2021-03-25 11:29:34,646 | /home/frappe/frappe-bench/apps/frappe/frappe/utils/scheduler.py:
Site: site1.local
Exception in Enqueue Events for Site site1.local
Traceback (most recent call last):
  File "/home/frappe/frappe-bench/env/lib/python3.6/site-packages/pymysql/connections.py", line 583, in connect
    **kwargs)
  File "/usr/lib/python3.6/socket.py", line 724, in create_connection
    raise err
  File "/usr/lib/python3.6/socket.py", line 713, in create_connection
    sock.connect(sa)
ConnectionRefusedError: [Errno 111] Connection refused

During handling of the above exception, another exception occurred:

Traceback (most recent call last):
  File "/home/frappe/frappe-bench/apps/frappe/frappe/utils/scheduler.py", line 81, in enqueue_events_for_site
    if is_scheduler_inactive():
  File "/home/frappe/frappe-bench/apps/frappe/frappe/utils/scheduler.py", line 228, in is_scheduler_inactive
    if is_scheduler_disabled():
  File "/home/frappe/frappe-bench/apps/frappe/frappe/utils/scheduler.py", line 237, in is_scheduler_disabled
    return not frappe.utils.cint(frappe.db.get_single_value("System Settings", "enable_scheduler"))
  File "/home/frappe/frappe-bench/apps/frappe/frappe/database/database.py", line 553, in get_single_value
    `tabSingles` where `doctype`=%s and `field`=%s""", (doctype, fieldname))
  File "/home/frappe/frappe-bench/apps/frappe/frappe/database/database.py", line 122, in sql
    self.connect()
  File "/home/frappe/frappe-bench/apps/frappe/frappe/database/database.py", line 75, in connect
    self._conn = self.get_connection()
  File "/home/frappe/frappe-bench/apps/frappe/frappe/database/mariadb/database.py", line 90, in get_connection
    local_infile = frappe.conf.local_infile)
  File "/home/frappe/frappe-bench/env/lib/python3.6/site-packages/pymysql/__init__.py", line 94, in Connect
    return Connection(*args, **kwargs)
  File "/home/frappe/frappe-bench/env/lib/python3.6/site-packages/pymysql/connections.py", line 325, in __init__
    self.connect()
  File "/home/frappe/frappe-bench/env/lib/python3.6/site-packages/pymysql/connections.py", line 630, in connect
    raise exc
pymysql.err.OperationalError: (2003, "Can't connect to MySQL server on 'localhost' ([Errno 111] Connection refused)")

[ERROR] 2021-03-25 11:30:34,834 | /home/frappe/frappe-bench/apps/frappe/frappe/utils/scheduler.py:
Site: site1.local
Exception in Enqueue Events for Site site1.local
Traceback (most recent call last):
  File "/home/frappe/frappe-bench/env/lib/python3.6/site-packages/pymysql/connections.py", line 583, in connect
    **kwargs)
  File "/usr/lib/python3.6/socket.py", line 724, in create_connection
    raise err
  File "/usr/lib/python3.6/socket.py", line 713, in create_connection
    sock.connect(sa)
ConnectionRefusedError: [Errno 111] Connection refused

During handling of the above exception, another exception occurred:

Traceback (most recent call last):
  File "/home/frappe/frappe-bench/apps/frappe/frappe/utils/scheduler.py", line 81, in enqueue_events_for_site
    if is_scheduler_inactive():
  File "/home/frappe/frappe-bench/apps/frappe/frappe/utils/scheduler.py", line 228, in is_scheduler_inactive
    if is_scheduler_disabled():
  File "/home/frappe/frappe-bench/apps/frappe/frappe/utils/scheduler.py", line 237, in is_scheduler_disabled
    return not frappe.utils.cint(frappe.db.get_single_value("System Settings", "enable_scheduler"))
  File "/home/frappe/frappe-bench/apps/frappe/frappe/database/database.py", line 553, in get_single_value
    `tabSingles` where `doctype`=%s and `field`=%s""", (doctype, fieldname))
  File "/home/frappe/frappe-bench/apps/frappe/frappe/database/database.py", line 122, in sql
    self.connect()
  File "/home/frappe/frappe-bench/apps/frappe/frappe/database/database.py", line 75, in connect
    self._conn = self.get_connection()
  File "/home/frappe/frappe-bench/apps/frappe/frappe/database/mariadb/database.py", line 90, in get_connection
    local_infile = frappe.conf.local_infile)
  File "/home/frappe/frappe-bench/env/lib/python3.6/site-packages/pymysql/__init__.py", line 94, in Connect
    return Connection(*args, **kwargs)
  File "/home/frappe/frappe-bench/env/lib/python3.6/site-packages/pymysql/connections.py", line 325, in __init__
    self.connect()
  File "/home/frappe/frappe-bench/env/lib/python3.6/site-packages/pymysql/connections.py", line 630, in connect
    raise exc
pymysql.err.OperationalError: (2003, "Can't connect to MySQL server on 'localhost' ([Errno 111] Connection refused)")

[ERROR] 2021-03-25 11:31:34,987 | /home/frappe/frappe-bench/apps/frappe/frappe/utils/scheduler.py:
Site: site1.local
Exception in Enqueue Events for Site site1.local
Traceback (most recent call last):
  File "/home/frappe/frappe-bench/env/lib/python3.6/site-packages/pymysql/connections.py", line 583, in connect
    **kwargs)
  File "/usr/lib/python3.6/socket.py", line 724, in create_connection
    raise err
  File "/usr/lib/python3.6/socket.py", line 713, in create_connection
    sock.connect(sa)
ConnectionRefusedError: [Errno 111] Connection refused

During handling of the above exception, another exception occurred:

Traceback (most recent call last):
  File "/home/frappe/frappe-bench/apps/frappe/frappe/utils/scheduler.py", line 81, in enqueue_events_for_site
    if is_scheduler_inactive():
  File "/home/frappe/frappe-bench/apps/frappe/frappe/utils/scheduler.py", line 228, in is_scheduler_inactive
    if is_scheduler_disabled():
  File "/home/frappe/frappe-bench/apps/frappe/frappe/utils/scheduler.py", line 237, in is_scheduler_disabled
    return not frappe.utils.cint(frappe.db.get_single_value("System Settings", "enable_scheduler"))
  File "/home/frappe/frappe-bench/apps/frappe/frappe/database/database.py", line 553, in get_single_value
    `tabSingles` where `doctype`=%s and `field`=%s""", (doctype, fieldname))
  File "/home/frappe/frappe-bench/apps/frappe/frappe/database/database.py", line 122, in sql
    self.connect()
  File "/home/frappe/frappe-bench/apps/frappe/frappe/database/database.py", line 75, in connect
    self._conn = self.get_connection()
  File "/home/frappe/frappe-bench/apps/frappe/frappe/database/mariadb/database.py", line 90, in get_connection
    local_infile = frappe.conf.local_infile)
  File "/home/frappe/frappe-bench/env/lib/python3.6/site-packages/pymysql/__init__.py", line 94, in Connect
    return Connection(*args, **kwargs)
  File "/home/frappe/frappe-bench/env/lib/python3.6/site-packages/pymysql/connections.py", line 325, in __init__
    self.connect()
  File "/home/frappe/frappe-bench/env/lib/python3.6/site-packages/pymysql/connections.py", line 630, in connect
    raise exc
pymysql.err.OperationalError: (2003, "Can't connect to MySQL server on 'localhost' ([Errno 111] Connection refused)")

[ERROR] 2021-03-25 11:32:35,146 | /home/frappe/frappe-bench/apps/frappe/frappe/utils/scheduler.py:
Site: site1.local
Exception in Enqueue Events for Site site1.local
Traceback (most recent call last):
  File "/home/frappe/frappe-bench/env/lib/python3.6/site-packages/pymysql/connections.py", line 583, in connect
    **kwargs)
  File "/usr/lib/python3.6/socket.py", line 724, in create_connection
    raise err
  File "/usr/lib/python3.6/socket.py", line 713, in create_connection
    sock.connect(sa)
ConnectionRefusedError: [Errno 111] Connection refused

During handling of the above exception, another exception occurred:

Traceback (most recent call last):
  File "/home/frappe/frappe-bench/apps/frappe/frappe/utils/scheduler.py", line 81, in enqueue_events_for_site
    if is_scheduler_inactive():
  File "/home/frappe/frappe-bench/apps/frappe/frappe/utils/scheduler.py", line 228, in is_scheduler_inactive
    if is_scheduler_disabled():
  File "/home/frappe/frappe-bench/apps/frappe/frappe/utils/scheduler.py", line 237, in is_scheduler_disabled
    return not frappe.utils.cint(frappe.db.get_single_value("System Settings", "enable_scheduler"))
  File "/home/frappe/frappe-bench/apps/frappe/frappe/database/database.py", line 553, in get_single_value
    `tabSingles` where `doctype`=%s and `field`=%s""", (doctype, fieldname))
  File "/home/frappe/frappe-bench/apps/frappe/frappe/database/database.py", line 122, in sql
    self.connect()
  File "/home/frappe/frappe-bench/apps/frappe/frappe/database/database.py", line 75, in connect
    self._conn = self.get_connection()
  File "/home/frappe/frappe-bench/apps/frappe/frappe/database/mariadb/database.py", line 90, in get_connection
    local_infile = frappe.conf.local_infile)
  File "/home/frappe/frappe-bench/env/lib/python3.6/site-packages/pymysql/__init__.py", line 94, in Connect
    return Connection(*args, **kwargs)
  File "/home/frappe/frappe-bench/env/lib/python3.6/site-packages/pymysql/connections.py", line 325, in __init__
    self.connect()
  File "/home/frappe/frappe-bench/env/lib/python3.6/site-packages/pymysql/connections.py", line 630, in connect
    raise exc
pymysql.err.OperationalError: (2003, "Can't connect to MySQL server on 'localhost' ([Errno 111] Connection refused)")

[ERROR] 2021-03-25 11:33:35,421 | /home/frappe/frappe-bench/apps/frappe/frappe/utils/scheduler.py:
Site: site1.local
Exception in Enqueue Events for Site site1.local
Traceback (most recent call last):
  File "/home/frappe/frappe-bench/env/lib/python3.6/site-packages/pymysql/connections.py", line 583, in connect
    **kwargs)
  File "/usr/lib/python3.6/socket.py", line 724, in create_connection
    raise err
  File "/usr/lib/python3.6/socket.py", line 713, in create_connection
    sock.connect(sa)
ConnectionRefusedError: [Errno 111] Connection refused

During handling of the above exception, another exception occurred:

Traceback (most recent call last):
  File "/home/frappe/frappe-bench/apps/frappe/frappe/utils/scheduler.py", line 81, in enqueue_events_for_site
    if is_scheduler_inactive():
  File "/home/frappe/frappe-bench/apps/frappe/frappe/utils/scheduler.py", line 228, in is_scheduler_inactive
    if is_scheduler_disabled():
  File "/home/frappe/frappe-bench/apps/frappe/frappe/utils/scheduler.py", line 237, in is_scheduler_disabled
    return not frappe.utils.cint(frappe.db.get_single_value("System Settings", "enable_scheduler"))
  File "/home/frappe/frappe-bench/apps/frappe/frappe/database/database.py", line 553, in get_single_value
    `tabSingles` where `doctype`=%s and `field`=%s""", (doctype, fieldname))
  File "/home/frappe/frappe-bench/apps/frappe/frappe/database/database.py", line 122, in sql
    self.connect()
  File "/home/frappe/frappe-bench/apps/frappe/frappe/database/database.py", line 75, in connect
    self._conn = self.get_connection()
  File "/home/frappe/frappe-bench/apps/frappe/frappe/database/mariadb/database.py", line 90, in get_connection
    local_infile = frappe.conf.local_infile)
  File "/home/frappe/frappe-bench/env/lib/python3.6/site-packages/pymysql/__init__.py", line 94, in Connect
    return Connection(*args, **kwargs)
  File "/home/frappe/frappe-bench/env/lib/python3.6/site-packages/pymysql/connections.py", line 325, in __init__
    self.connect()
  File "/home/frappe/frappe-bench/env/lib/python3.6/site-packages/pymysql/connections.py", line 630, in connect
    raise exc
pymysql.err.OperationalError: (2003, "Can't connect to MySQL server on 'localhost' ([Errno 111] Connection refused)")

[ERROR] 2021-03-25 11:34:35,620 | /home/frappe/frappe-bench/apps/frappe/frappe/utils/scheduler.py:
Site: site1.local
Exception in Enqueue Events for Site site1.local
Traceback (most recent call last):
  File "/home/frappe/frappe-bench/env/lib/python3.6/site-packages/pymysql/connections.py", line 583, in connect
    **kwargs)
  File "/usr/lib/python3.6/socket.py", line 724, in create_connection
    raise err
  File "/usr/lib/python3.6/socket.py", line 713, in create_connection
    sock.connect(sa)
ConnectionRefusedError: [Errno 111] Connection refused

During handling of the above exception, another exception occurred:

Traceback (most recent call last):
  File "/home/frappe/frappe-bench/apps/frappe/frappe/utils/scheduler.py", line 81, in enqueue_events_for_site
    if is_scheduler_inactive():
  File "/home/frappe/frappe-bench/apps/frappe/frappe/utils/scheduler.py", line 228, in is_scheduler_inactive
    if is_scheduler_disabled():
  File "/home/frappe/frappe-bench/apps/frappe/frappe/utils/scheduler.py", line 237, in is_scheduler_disabled
    return not frappe.utils.cint(frappe.db.get_single_value("System Settings", "enable_scheduler"))
  File "/home/frappe/frappe-bench/apps/frappe/frappe/database/database.py", line 553, in get_single_value
    `tabSingles` where `doctype`=%s and `field`=%s""", (doctype, fieldname))
  File "/home/frappe/frappe-bench/apps/frappe/frappe/database/database.py", line 122, in sql
    self.connect()
  File "/home/frappe/frappe-bench/apps/frappe/frappe/database/database.py", line 75, in connect
    self._conn = self.get_connection()
  File "/home/frappe/frappe-bench/apps/frappe/frappe/database/mariadb/database.py", line 90, in get_connection
    local_infile = frappe.conf.local_infile)
  File "/home/frappe/frappe-bench/env/lib/python3.6/site-packages/pymysql/__init__.py", line 94, in Connect
    return Connection(*args, **kwargs)
  File "/home/frappe/frappe-bench/env/lib/python3.6/site-packages/pymysql/connections.py", line 325, in __init__
    self.connect()
  File "/home/frappe/frappe-bench/env/lib/python3.6/site-packages/pymysql/connections.py", line 630, in connect
    raise exc
pymysql.err.OperationalError: (2003, "Can't connect to MySQL server on 'localhost' ([Errno 111] Connection refused)")

[ERROR] 2021-03-25 11:35:35,944 | /home/frappe/frappe-bench/apps/frappe/frappe/utils/scheduler.py:
Site: site1.local
Exception in Enqueue Events for Site site1.local
Traceback (most recent call last):
  File "/home/frappe/frappe-bench/env/lib/python3.6/site-packages/pymysql/connections.py", line 583, in connect
    **kwargs)
  File "/usr/lib/python3.6/socket.py", line 724, in create_connection
    raise err
  File "/usr/lib/python3.6/socket.py", line 713, in create_connection
    sock.connect(sa)
ConnectionRefusedError: [Errno 111] Connection refused

During handling of the above exception, another exception occurred:

Traceback (most recent call last):
  File "/home/frappe/frappe-bench/apps/frappe/frappe/utils/scheduler.py", line 81, in enqueue_events_for_site
    if is_scheduler_inactive():
  File "/home/frappe/frappe-bench/apps/frappe/frappe/utils/scheduler.py", line 228, in is_scheduler_inactive
    if is_scheduler_disabled():
  File "/home/frappe/frappe-bench/apps/frappe/frappe/utils/scheduler.py", line 237, in is_scheduler_disabled
    return not frappe.utils.cint(frappe.db.get_single_value("System Settings", "enable_scheduler"))
  File "/home/frappe/frappe-bench/apps/frappe/frappe/database/database.py", line 553, in get_single_value
    `tabSingles` where `doctype`=%s and `field`=%s""", (doctype, fieldname))
  File "/home/frappe/frappe-bench/apps/frappe/frappe/database/database.py", line 122, in sql
    self.connect()
  File "/home/frappe/frappe-bench/apps/frappe/frappe/database/database.py", line 75, in connect
    self._conn = self.get_connection()
  File "/home/frappe/frappe-bench/apps/frappe/frappe/database/mariadb/database.py", line 90, in get_connection
    local_infile = frappe.conf.local_infile)
  File "/home/frappe/frappe-bench/env/lib/python3.6/site-packages/pymysql/__init__.py", line 94, in Connect
    return Connection(*args, **kwargs)
  File "/home/frappe/frappe-bench/env/lib/python3.6/site-packages/pymysql/connections.py", line 325, in __init__
    self.connect()
  File "/home/frappe/frappe-bench/env/lib/python3.6/site-packages/pymysql/connections.py", line 630, in connect
    raise exc
pymysql.err.OperationalError: (2003, "Can't connect to MySQL server on 'localhost' ([Errno 111] Connection refused)")

[ERROR] 2021-03-25 11:36:36,574 | /home/frappe/frappe-bench/apps/frappe/frappe/utils/scheduler.py:
Site: site1.local
Exception in Enqueue Events for Site site1.local
Traceback (most recent call last):
  File "/home/frappe/frappe-bench/env/lib/python3.6/site-packages/pymysql/connections.py", line 583, in connect
    **kwargs)
  File "/usr/lib/python3.6/socket.py", line 724, in create_connection
    raise err
  File "/usr/lib/python3.6/socket.py", line 713, in create_connection
    sock.connect(sa)
ConnectionRefusedError: [Errno 111] Connection refused

During handling of the above exception, another exception occurred:

Traceback (most recent call last):
  File "/home/frappe/frappe-bench/apps/frappe/frappe/utils/scheduler.py", line 81, in enqueue_events_for_site
    if is_scheduler_inactive():
  File "/home/frappe/frappe-bench/apps/frappe/frappe/utils/scheduler.py", line 228, in is_scheduler_inactive
    if is_scheduler_disabled():
  File "/home/frappe/frappe-bench/apps/frappe/frappe/utils/scheduler.py", line 237, in is_scheduler_disabled
    return not frappe.utils.cint(frappe.db.get_single_value("System Settings", "enable_scheduler"))
  File "/home/frappe/frappe-bench/apps/frappe/frappe/database/database.py", line 553, in get_single_value
    `tabSingles` where `doctype`=%s and `field`=%s""", (doctype, fieldname))
  File "/home/frappe/frappe-bench/apps/frappe/frappe/database/database.py", line 122, in sql
    self.connect()
  File "/home/frappe/frappe-bench/apps/frappe/frappe/database/database.py", line 75, in connect
    self._conn = self.get_connection()
  File "/home/frappe/frappe-bench/apps/frappe/frappe/database/mariadb/database.py", line 90, in get_connection
    local_infile = frappe.conf.local_infile)
  File "/home/frappe/frappe-bench/env/lib/python3.6/site-packages/pymysql/__init__.py", line 94, in Connect
    return Connection(*args, **kwargs)
  File "/home/frappe/frappe-bench/env/lib/python3.6/site-packages/pymysql/connections.py", line 325, in __init__
    self.connect()
  File "/home/frappe/frappe-bench/env/lib/python3.6/site-packages/pymysql/connections.py", line 630, in connect
    raise exc
pymysql.err.OperationalError: (2003, "Can't connect to MySQL server on 'localhost' ([Errno 111] Connection refused)")

[ERROR] 2021-03-25 11:37:36,804 | /home/frappe/frappe-bench/apps/frappe/frappe/utils/scheduler.py:
Site: site1.local
Exception in Enqueue Events for Site site1.local
Traceback (most recent call last):
  File "/home/frappe/frappe-bench/env/lib/python3.6/site-packages/pymysql/connections.py", line 583, in connect
    **kwargs)
  File "/usr/lib/python3.6/socket.py", line 724, in create_connection
    raise err
  File "/usr/lib/python3.6/socket.py", line 713, in create_connection
    sock.connect(sa)
ConnectionRefusedError: [Errno 111] Connection refused

During handling of the above exception, another exception occurred:

Traceback (most recent call last):
  File "/home/frappe/frappe-bench/apps/frappe/frappe/utils/scheduler.py", line 81, in enqueue_events_for_site
    if is_scheduler_inactive():
  File "/home/frappe/frappe-bench/apps/frappe/frappe/utils/scheduler.py", line 228, in is_scheduler_inactive
    if is_scheduler_disabled():
  File "/home/frappe/frappe-bench/apps/frappe/frappe/utils/scheduler.py", line 237, in is_scheduler_disabled
    return not frappe.utils.cint(frappe.db.get_single_value("System Settings", "enable_scheduler"))
  File "/home/frappe/frappe-bench/apps/frappe/frappe/database/database.py", line 553, in get_single_value
    `tabSingles` where `doctype`=%s and `field`=%s""", (doctype, fieldname))
  File "/home/frappe/frappe-bench/apps/frappe/frappe/database/database.py", line 122, in sql
    self.connect()
  File "/home/frappe/frappe-bench/apps/frappe/frappe/database/database.py", line 75, in connect
    self._conn = self.get_connection()
  File "/home/frappe/frappe-bench/apps/frappe/frappe/database/mariadb/database.py", line 90, in get_connection
    local_infile = frappe.conf.local_infile)
  File "/home/frappe/frappe-bench/env/lib/python3.6/site-packages/pymysql/__init__.py", line 94, in Connect
    return Connection(*args, **kwargs)
  File "/home/frappe/frappe-bench/env/lib/python3.6/site-packages/pymysql/connections.py", line 325, in __init__
    self.connect()
  File "/home/frappe/frappe-bench/env/lib/python3.6/site-packages/pymysql/connections.py", line 630, in connect
    raise exc
pymysql.err.OperationalError: (2003, "Can't connect to MySQL server on 'localhost' ([Errno 111] Connection refused)")

[ERROR] 2021-03-25 11:38:37,198 | /home/frappe/frappe-bench/apps/frappe/frappe/utils/scheduler.py:
Site: site1.local
Exception in Enqueue Events for Site site1.local
Traceback (most recent call last):
  File "/home/frappe/frappe-bench/env/lib/python3.6/site-packages/pymysql/connections.py", line 583, in connect
    **kwargs)
  File "/usr/lib/python3.6/socket.py", line 724, in create_connection
    raise err
  File "/usr/lib/python3.6/socket.py", line 713, in create_connection
    sock.connect(sa)
ConnectionRefusedError: [Errno 111] Connection refused

During handling of the above exception, another exception occurred:

Traceback (most recent call last):
  File "/home/frappe/frappe-bench/apps/frappe/frappe/utils/scheduler.py", line 81, in enqueue_events_for_site
    if is_scheduler_inactive():
  File "/home/frappe/frappe-bench/apps/frappe/frappe/utils/scheduler.py", line 228, in is_scheduler_inactive
    if is_scheduler_disabled():
  File "/home/frappe/frappe-bench/apps/frappe/frappe/utils/scheduler.py", line 237, in is_scheduler_disabled
    return not frappe.utils.cint(frappe.db.get_single_value("System Settings", "enable_scheduler"))
  File "/home/frappe/frappe-bench/apps/frappe/frappe/database/database.py", line 553, in get_single_value
    `tabSingles` where `doctype`=%s and `field`=%s""", (doctype, fieldname))
  File "/home/frappe/frappe-bench/apps/frappe/frappe/database/database.py", line 122, in sql
    self.connect()
  File "/home/frappe/frappe-bench/apps/frappe/frappe/database/database.py", line 75, in connect
    self._conn = self.get_connection()
  File "/home/frappe/frappe-bench/apps/frappe/frappe/database/mariadb/database.py", line 90, in get_connection
    local_infile = frappe.conf.local_infile)
  File "/home/frappe/frappe-bench/env/lib/python3.6/site-packages/pymysql/__init__.py", line 94, in Connect
    return Connection(*args, **kwargs)
  File "/home/frappe/frappe-bench/env/lib/python3.6/site-packages/pymysql/connections.py", line 325, in __init__
    self.connect()
  File "/home/frappe/frappe-bench/env/lib/python3.6/site-packages/pymysql/connections.py", line 630, in connect
    raise exc
pymysql.err.OperationalError: (2003, "Can't connect to MySQL server on 'localhost' ([Errno 111] Connection refused)")

[ERROR] 2021-03-25 11:39:37,459 | /home/frappe/frappe-bench/apps/frappe/frappe/utils/scheduler.py:
Site: site1.local
Exception in Enqueue Events for Site site1.local
Traceback (most recent call last):
  File "/home/frappe/frappe-bench/env/lib/python3.6/site-packages/pymysql/connections.py", line 583, in connect
    **kwargs)
  File "/usr/lib/python3.6/socket.py", line 724, in create_connection
    raise err
  File "/usr/lib/python3.6/socket.py", line 713, in create_connection
    sock.connect(sa)
ConnectionRefusedError: [Errno 111] Connection refused

During handling of the above exception, another exception occurred:

Traceback (most recent call last):
  File "/home/frappe/frappe-bench/apps/frappe/frappe/utils/scheduler.py", line 81, in enqueue_events_for_site
    if is_scheduler_inactive():
  File "/home/frappe/frappe-bench/apps/frappe/frappe/utils/scheduler.py", line 228, in is_scheduler_inactive
    if is_scheduler_disabled():
  File "/home/frappe/frappe-bench/apps/frappe/frappe/utils/scheduler.py", line 237, in is_scheduler_disabled
    return not frappe.utils.cint(frappe.db.get_single_value("System Settings", "enable_scheduler"))
  File "/home/frappe/frappe-bench/apps/frappe/frappe/database/database.py", line 553, in get_single_value
    `tabSingles` where `doctype`=%s and `field`=%s""", (doctype, fieldname))
  File "/home/frappe/frappe-bench/apps/frappe/frappe/database/database.py", line 122, in sql
    self.connect()
  File "/home/frappe/frappe-bench/apps/frappe/frappe/database/database.py", line 75, in connect
    self._conn = self.get_connection()
  File "/home/frappe/frappe-bench/apps/frappe/frappe/database/mariadb/database.py", line 90, in get_connection
    local_infile = frappe.conf.local_infile)
  File "/home/frappe/frappe-bench/env/lib/python3.6/site-packages/pymysql/__init__.py", line 94, in Connect
    return Connection(*args, **kwargs)
  File "/home/frappe/frappe-bench/env/lib/python3.6/site-packages/pymysql/connections.py", line 325, in __init__
    self.connect()
  File "/home/frappe/frappe-bench/env/lib/python3.6/site-packages/pymysql/connections.py", line 630, in connect
    raise exc
pymysql.err.OperationalError: (2003, "Can't connect to MySQL server on 'localhost' ([Errno 111] Connection refused)")

[ERROR] 2021-03-25 11:40:37,571 | /home/frappe/frappe-bench/apps/frappe/frappe/utils/scheduler.py:
Site: site1.local
Exception in Enqueue Events for Site site1.local
Traceback (most recent call last):
  File "/home/frappe/frappe-bench/env/lib/python3.6/site-packages/pymysql/connections.py", line 583, in connect
    **kwargs)
  File "/usr/lib/python3.6/socket.py", line 724, in create_connection
    raise err
  File "/usr/lib/python3.6/socket.py", line 713, in create_connection
    sock.connect(sa)
ConnectionRefusedError: [Errno 111] Connection refused

During handling of the above exception, another exception occurred:

Traceback (most recent call last):
  File "/home/frappe/frappe-bench/apps/frappe/frappe/utils/scheduler.py", line 81, in enqueue_events_for_site
    if is_scheduler_inactive():
  File "/home/frappe/frappe-bench/apps/frappe/frappe/utils/scheduler.py", line 228, in is_scheduler_inactive
    if is_scheduler_disabled():
  File "/home/frappe/frappe-bench/apps/frappe/frappe/utils/scheduler.py", line 237, in is_scheduler_disabled
    return not frappe.utils.cint(frappe.db.get_single_value("System Settings", "enable_scheduler"))
  File "/home/frappe/frappe-bench/apps/frappe/frappe/database/database.py", line 553, in get_single_value
    `tabSingles` where `doctype`=%s and `field`=%s""", (doctype, fieldname))
  File "/home/frappe/frappe-bench/apps/frappe/frappe/database/database.py", line 122, in sql
    self.connect()
  File "/home/frappe/frappe-bench/apps/frappe/frappe/database/database.py", line 75, in connect
    self._conn = self.get_connection()
  File "/home/frappe/frappe-bench/apps/frappe/frappe/database/mariadb/database.py", line 90, in get_connection
    local_infile = frappe.conf.local_infile)
  File "/home/frappe/frappe-bench/env/lib/python3.6/site-packages/pymysql/__init__.py", line 94, in Connect
    return Connection(*args, **kwargs)
  File "/home/frappe/frappe-bench/env/lib/python3.6/site-packages/pymysql/connections.py", line 325, in __init__
    self.connect()
  File "/home/frappe/frappe-bench/env/lib/python3.6/site-packages/pymysql/connections.py", line 630, in connect
    raise exc
pymysql.err.OperationalError: (2003, "Can't connect to MySQL server on 'localhost' ([Errno 111] Connection refused)")

[ERROR] 2021-03-25 11:41:37,744 | /home/frappe/frappe-bench/apps/frappe/frappe/utils/scheduler.py:
Site: site1.local
Exception in Enqueue Events for Site site1.local
Traceback (most recent call last):
  File "/home/frappe/frappe-bench/env/lib/python3.6/site-packages/pymysql/connections.py", line 583, in connect
    **kwargs)
  File "/usr/lib/python3.6/socket.py", line 724, in create_connection
    raise err
  File "/usr/lib/python3.6/socket.py", line 713, in create_connection
    sock.connect(sa)
ConnectionRefusedError: [Errno 111] Connection refused

During handling of the above exception, another exception occurred:

Traceback (most recent call last):
  File "/home/frappe/frappe-bench/apps/frappe/frappe/utils/scheduler.py", line 81, in enqueue_events_for_site
    if is_scheduler_inactive():
  File "/home/frappe/frappe-bench/apps/frappe/frappe/utils/scheduler.py", line 228, in is_scheduler_inactive
    if is_scheduler_disabled():
  File "/home/frappe/frappe-bench/apps/frappe/frappe/utils/scheduler.py", line 237, in is_scheduler_disabled
    return not frappe.utils.cint(frappe.db.get_single_value("System Settings", "enable_scheduler"))
  File "/home/frappe/frappe-bench/apps/frappe/frappe/database/database.py", line 553, in get_single_value
    `tabSingles` where `doctype`=%s and `field`=%s""", (doctype, fieldname))
  File "/home/frappe/frappe-bench/apps/frappe/frappe/database/database.py", line 122, in sql
    self.connect()
  File "/home/frappe/frappe-bench/apps/frappe/frappe/database/database.py", line 75, in connect
    self._conn = self.get_connection()
  File "/home/frappe/frappe-bench/apps/frappe/frappe/database/mariadb/database.py", line 90, in get_connection
    local_infile = frappe.conf.local_infile)
  File "/home/frappe/frappe-bench/env/lib/python3.6/site-packages/pymysql/__init__.py", line 94, in Connect
    return Connection(*args, **kwargs)
  File "/home/frappe/frappe-bench/env/lib/python3.6/site-packages/pymysql/connections.py", line 325, in __init__
    self.connect()
  File "/home/frappe/frappe-bench/env/lib/python3.6/site-packages/pymysql/connections.py", line 630, in connect
    raise exc
pymysql.err.OperationalError: (2003, "Can't connect to MySQL server on 'localhost' ([Errno 111] Connection refused)")

[ERROR] 2021-03-25 11:42:37,992 | /home/frappe/frappe-bench/apps/frappe/frappe/utils/scheduler.py:
Site: site1.local
Exception in Enqueue Events for Site site1.local
Traceback (most recent call last):
  File "/home/frappe/frappe-bench/env/lib/python3.6/site-packages/pymysql/connections.py", line 583, in connect
    **kwargs)
  File "/usr/lib/python3.6/socket.py", line 724, in create_connection
    raise err
  File "/usr/lib/python3.6/socket.py", line 713, in create_connection
    sock.connect(sa)
ConnectionRefusedError: [Errno 111] Connection refused

During handling of the above exception, another exception occurred:

Traceback (most recent call last):
  File "/home/frappe/frappe-bench/apps/frappe/frappe/utils/scheduler.py", line 81, in enqueue_events_for_site
    if is_scheduler_inactive():
  File "/home/frappe/frappe-bench/apps/frappe/frappe/utils/scheduler.py", line 228, in is_scheduler_inactive
    if is_scheduler_disabled():
  File "/home/frappe/frappe-bench/apps/frappe/frappe/utils/scheduler.py", line 237, in is_scheduler_disabled
    return not frappe.utils.cint(frappe.db.get_single_value("System Settings", "enable_scheduler"))
  File "/home/frappe/frappe-bench/apps/frappe/frappe/database/database.py", line 553, in get_single_value
    `tabSingles` where `doctype`=%s and `field`=%s""", (doctype, fieldname))
  File "/home/frappe/frappe-bench/apps/frappe/frappe/database/database.py", line 122, in sql
    self.connect()
  File "/home/frappe/frappe-bench/apps/frappe/frappe/database/database.py", line 75, in connect
    self._conn = self.get_connection()
  File "/home/frappe/frappe-bench/apps/frappe/frappe/database/mariadb/database.py", line 90, in get_connection
    local_infile = frappe.conf.local_infile)
  File "/home/frappe/frappe-bench/env/lib/python3.6/site-packages/pymysql/__init__.py", line 94, in Connect
    return Connection(*args, **kwargs)
  File "/home/frappe/frappe-bench/env/lib/python3.6/site-packages/pymysql/connections.py", line 325, in __init__
    self.connect()
  File "/home/frappe/frappe-bench/env/lib/python3.6/site-packages/pymysql/connections.py", line 630, in connect
    raise exc
pymysql.err.OperationalError: (2003, "Can't connect to MySQL server on 'localhost' ([Errno 111] Connection refused)")

[ERROR] 2021-03-25 11:43:38,183 | /home/frappe/frappe-bench/apps/frappe/frappe/utils/scheduler.py:
Site: site1.local
Exception in Enqueue Events for Site site1.local
Traceback (most recent call last):
  File "/home/frappe/frappe-bench/env/lib/python3.6/site-packages/pymysql/connections.py", line 583, in connect
    **kwargs)
  File "/usr/lib/python3.6/socket.py", line 724, in create_connection
    raise err
  File "/usr/lib/python3.6/socket.py", line 713, in create_connection
    sock.connect(sa)
ConnectionRefusedError: [Errno 111] Connection refused

During handling of the above exception, another exception occurred:

Traceback (most recent call last):
  File "/home/frappe/frappe-bench/apps/frappe/frappe/utils/scheduler.py", line 81, in enqueue_events_for_site
    if is_scheduler_inactive():
  File "/home/frappe/frappe-bench/apps/frappe/frappe/utils/scheduler.py", line 228, in is_scheduler_inactive
    if is_scheduler_disabled():
  File "/home/frappe/frappe-bench/apps/frappe/frappe/utils/scheduler.py", line 237, in is_scheduler_disabled
    return not frappe.utils.cint(frappe.db.get_single_value("System Settings", "enable_scheduler"))
  File "/home/frappe/frappe-bench/apps/frappe/frappe/database/database.py", line 553, in get_single_value
    `tabSingles` where `doctype`=%s and `field`=%s""", (doctype, fieldname))
  File "/home/frappe/frappe-bench/apps/frappe/frappe/database/database.py", line 122, in sql
    self.connect()
  File "/home/frappe/frappe-bench/apps/frappe/frappe/database/database.py", line 75, in connect
    self._conn = self.get_connection()
  File "/home/frappe/frappe-bench/apps/frappe/frappe/database/mariadb/database.py", line 90, in get_connection
    local_infile = frappe.conf.local_infile)
  File "/home/frappe/frappe-bench/env/lib/python3.6/site-packages/pymysql/__init__.py", line 94, in Connect
    return Connection(*args, **kwargs)
  File "/home/frappe/frappe-bench/env/lib/python3.6/site-packages/pymysql/connections.py", line 325, in __init__
    self.connect()
  File "/home/frappe/frappe-bench/env/lib/python3.6/site-packages/pymysql/connections.py", line 630, in connect
    raise exc
pymysql.err.OperationalError: (2003, "Can't connect to MySQL server on 'localhost' ([Errno 111] Connection refused)")

[ERROR] 2021-03-25 11:44:26,099 | /home/frappe/frappe-bench/apps/frappe/frappe/app.py:
Site: site1.local
Request Error
Traceback (most recent call last):
  File "/home/frappe/frappe-bench/env/lib/python3.6/site-packages/pymysql/connections.py", line 583, in connect
    **kwargs)
  File "/usr/lib/python3.6/socket.py", line 724, in create_connection
    raise err
  File "/usr/lib/python3.6/socket.py", line 713, in create_connection
    sock.connect(sa)
ConnectionRefusedError: [Errno 111] Connection refused

During handling of the above exception, another exception occurred:

Traceback (most recent call last):
  File "/home/frappe/frappe-bench/apps/frappe/frappe/app.py", line 54, in application
    init_request(request)
  File "/home/frappe/frappe-bench/apps/frappe/frappe/app.py", line 126, in init_request
    frappe.local.http_request = frappe.auth.HTTPRequest()
  File "/home/frappe/frappe-bench/apps/frappe/frappe/auth.py", line 42, in __init__
    self.set_lang()
  File "/home/frappe/frappe-bench/apps/frappe/frappe/auth.py", line 86, in set_lang
    frappe.local.lang = guess_language()
  File "/home/frappe/frappe-bench/apps/frappe/frappe/translate.py", line 29, in guess_language
    lang_list = get_all_languages() or []
  File "/home/frappe/frappe-bench/apps/frappe/frappe/translate.py", line 85, in get_all_languages
    return frappe.cache().get_value('languages', _get)
  File "/home/frappe/frappe-bench/apps/frappe/frappe/utils/redis_wrapper.py", line 79, in get_value
    val = generator()
  File "/home/frappe/frappe-bench/apps/frappe/frappe/translate.py", line 84, in _get
    return frappe.db.sql_list('select name from tabLanguage')
  File "/home/frappe/frappe-bench/apps/frappe/frappe/database/database.py", line 236, in sql_list
    return [r[0] for r in self.sql(query, values, debug=debug)]
  File "/home/frappe/frappe-bench/apps/frappe/frappe/database/database.py", line 122, in sql
    self.connect()
  File "/home/frappe/frappe-bench/apps/frappe/frappe/database/database.py", line 75, in connect
    self._conn = self.get_connection()
  File "/home/frappe/frappe-bench/apps/frappe/frappe/database/mariadb/database.py", line 90, in get_connection
    local_infile = frappe.conf.local_infile)
  File "/home/frappe/frappe-bench/env/lib/python3.6/site-packages/pymysql/__init__.py", line 94, in Connect
    return Connection(*args, **kwargs)
  File "/home/frappe/frappe-bench/env/lib/python3.6/site-packages/pymysql/connections.py", line 325, in __init__
    self.connect()
  File "/home/frappe/frappe-bench/env/lib/python3.6/site-packages/pymysql/connections.py", line 630, in connect
    raise exc
pymysql.err.OperationalError: (2003, "Can't connect to MySQL server on 'localhost' ([Errno 111] Connection refused)")
[ERROR] 2021-03-25 11:44:26,157 | /home/frappe/frappe-bench/apps/frappe/frappe/utils/error.py:
New Exception collected with id: 2021-03-25 11:44:26.099889-10.0.2.2-0c0
[ERROR] 2021-03-25 11:44:26,302 | /home/frappe/frappe-bench/apps/frappe/frappe/app.py:
Site: site1.local
Request Error
Traceback (most recent call last):
  File "/home/frappe/frappe-bench/env/lib/python3.6/site-packages/pymysql/connections.py", line 583, in connect
    **kwargs)
  File "/usr/lib/python3.6/socket.py", line 724, in create_connection
    raise err
  File "/usr/lib/python3.6/socket.py", line 713, in create_connection
    sock.connect(sa)
ConnectionRefusedError: [Errno 111] Connection refused

During handling of the above exception, another exception occurred:

Traceback (most recent call last):
  File "/home/frappe/frappe-bench/apps/frappe/frappe/app.py", line 54, in application
    init_request(request)
  File "/home/frappe/frappe-bench/apps/frappe/frappe/app.py", line 126, in init_request
    frappe.local.http_request = frappe.auth.HTTPRequest()
  File "/home/frappe/frappe-bench/apps/frappe/frappe/auth.py", line 42, in __init__
    self.set_lang()
  File "/home/frappe/frappe-bench/apps/frappe/frappe/auth.py", line 86, in set_lang
    frappe.local.lang = guess_language()
  File "/home/frappe/frappe-bench/apps/frappe/frappe/translate.py", line 29, in guess_language
    lang_list = get_all_languages() or []
  File "/home/frappe/frappe-bench/apps/frappe/frappe/translate.py", line 85, in get_all_languages
    return frappe.cache().get_value('languages', _get)
  File "/home/frappe/frappe-bench/apps/frappe/frappe/utils/redis_wrapper.py", line 79, in get_value
    val = generator()
  File "/home/frappe/frappe-bench/apps/frappe/frappe/translate.py", line 84, in _get
    return frappe.db.sql_list('select name from tabLanguage')
  File "/home/frappe/frappe-bench/apps/frappe/frappe/database/database.py", line 236, in sql_list
    return [r[0] for r in self.sql(query, values, debug=debug)]
  File "/home/frappe/frappe-bench/apps/frappe/frappe/database/database.py", line 122, in sql
    self.connect()
  File "/home/frappe/frappe-bench/apps/frappe/frappe/database/database.py", line 75, in connect
    self._conn = self.get_connection()
  File "/home/frappe/frappe-bench/apps/frappe/frappe/database/mariadb/database.py", line 90, in get_connection
    local_infile = frappe.conf.local_infile)
  File "/home/frappe/frappe-bench/env/lib/python3.6/site-packages/pymysql/__init__.py", line 94, in Connect
    return Connection(*args, **kwargs)
  File "/home/frappe/frappe-bench/env/lib/python3.6/site-packages/pymysql/connections.py", line 325, in __init__
    self.connect()
  File "/home/frappe/frappe-bench/env/lib/python3.6/site-packages/pymysql/connections.py", line 630, in connect
    raise exc
pymysql.err.OperationalError: (2003, "Can't connect to MySQL server on 'localhost' ([Errno 111] Connection refused)")
[ERROR] 2021-03-25 11:44:26,311 | /home/frappe/frappe-bench/apps/frappe/frappe/utils/error.py:
New Exception collected with id: 2021-03-25 11:44:26.303346-10.0.2.2-01d
[ERROR] 2021-03-25 11:44:27,581 | /home/frappe/frappe-bench/apps/frappe/frappe/app.py:
Site: site1.local
Request Error
Traceback (most recent call last):
  File "/home/frappe/frappe-bench/env/lib/python3.6/site-packages/pymysql/connections.py", line 583, in connect
    **kwargs)
  File "/usr/lib/python3.6/socket.py", line 724, in create_connection
    raise err
  File "/usr/lib/python3.6/socket.py", line 713, in create_connection
    sock.connect(sa)
ConnectionRefusedError: [Errno 111] Connection refused

During handling of the above exception, another exception occurred:

Traceback (most recent call last):
  File "/home/frappe/frappe-bench/apps/frappe/frappe/app.py", line 54, in application
    init_request(request)
  File "/home/frappe/frappe-bench/apps/frappe/frappe/app.py", line 126, in init_request
    frappe.local.http_request = frappe.auth.HTTPRequest()
  File "/home/frappe/frappe-bench/apps/frappe/frappe/auth.py", line 42, in __init__
    self.set_lang()
  File "/home/frappe/frappe-bench/apps/frappe/frappe/auth.py", line 86, in set_lang
    frappe.local.lang = guess_language()
  File "/home/frappe/frappe-bench/apps/frappe/frappe/translate.py", line 29, in guess_language
    lang_list = get_all_languages() or []
  File "/home/frappe/frappe-bench/apps/frappe/frappe/translate.py", line 85, in get_all_languages
    return frappe.cache().get_value('languages', _get)
  File "/home/frappe/frappe-bench/apps/frappe/frappe/utils/redis_wrapper.py", line 79, in get_value
    val = generator()
  File "/home/frappe/frappe-bench/apps/frappe/frappe/translate.py", line 84, in _get
    return frappe.db.sql_list('select name from tabLanguage')
  File "/home/frappe/frappe-bench/apps/frappe/frappe/database/database.py", line 236, in sql_list
    return [r[0] for r in self.sql(query, values, debug=debug)]
  File "/home/frappe/frappe-bench/apps/frappe/frappe/database/database.py", line 122, in sql
    self.connect()
  File "/home/frappe/frappe-bench/apps/frappe/frappe/database/database.py", line 75, in connect
    self._conn = self.get_connection()
  File "/home/frappe/frappe-bench/apps/frappe/frappe/database/mariadb/database.py", line 90, in get_connection
    local_infile = frappe.conf.local_infile)
  File "/home/frappe/frappe-bench/env/lib/python3.6/site-packages/pymysql/__init__.py", line 94, in Connect
    return Connection(*args, **kwargs)
  File "/home/frappe/frappe-bench/env/lib/python3.6/site-packages/pymysql/connections.py", line 325, in __init__
    self.connect()
  File "/home/frappe/frappe-bench/env/lib/python3.6/site-packages/pymysql/connections.py", line 630, in connect
    raise exc
pymysql.err.OperationalError: (2003, "Can't connect to MySQL server on 'localhost' ([Errno 111] Connection refused)")
[ERROR] 2021-03-25 11:44:27,635 | /home/frappe/frappe-bench/apps/frappe/frappe/utils/error.py:
New Exception collected with id: 2021-03-25 11:44:27.581762-10.0.2.2-f0e
[ERROR] 2021-03-25 11:44:27,751 | /home/frappe/frappe-bench/apps/frappe/frappe/app.py:
Site: site1.local
Request Error
Traceback (most recent call last):
  File "/home/frappe/frappe-bench/env/lib/python3.6/site-packages/pymysql/connections.py", line 583, in connect
    **kwargs)
  File "/usr/lib/python3.6/socket.py", line 724, in create_connection
    raise err
  File "/usr/lib/python3.6/socket.py", line 713, in create_connection
    sock.connect(sa)
ConnectionRefusedError: [Errno 111] Connection refused

During handling of the above exception, another exception occurred:

Traceback (most recent call last):
  File "/home/frappe/frappe-bench/apps/frappe/frappe/app.py", line 54, in application
    init_request(request)
  File "/home/frappe/frappe-bench/apps/frappe/frappe/app.py", line 126, in init_request
    frappe.local.http_request = frappe.auth.HTTPRequest()
  File "/home/frappe/frappe-bench/apps/frappe/frappe/auth.py", line 42, in __init__
    self.set_lang()
  File "/home/frappe/frappe-bench/apps/frappe/frappe/auth.py", line 86, in set_lang
    frappe.local.lang = guess_language()
  File "/home/frappe/frappe-bench/apps/frappe/frappe/translate.py", line 29, in guess_language
    lang_list = get_all_languages() or []
  File "/home/frappe/frappe-bench/apps/frappe/frappe/translate.py", line 85, in get_all_languages
    return frappe.cache().get_value('languages', _get)
  File "/home/frappe/frappe-bench/apps/frappe/frappe/utils/redis_wrapper.py", line 79, in get_value
    val = generator()
  File "/home/frappe/frappe-bench/apps/frappe/frappe/translate.py", line 84, in _get
    return frappe.db.sql_list('select name from tabLanguage')
  File "/home/frappe/frappe-bench/apps/frappe/frappe/database/database.py", line 236, in sql_list
    return [r[0] for r in self.sql(query, values, debug=debug)]
  File "/home/frappe/frappe-bench/apps/frappe/frappe/database/database.py", line 122, in sql
    self.connect()
  File "/home/frappe/frappe-bench/apps/frappe/frappe/database/database.py", line 75, in connect
    self._conn = self.get_connection()
  File "/home/frappe/frappe-bench/apps/frappe/frappe/database/mariadb/database.py", line 90, in get_connection
    local_infile = frappe.conf.local_infile)
  File "/home/frappe/frappe-bench/env/lib/python3.6/site-packages/pymysql/__init__.py", line 94, in Connect
    return Connection(*args, **kwargs)
  File "/home/frappe/frappe-bench/env/lib/python3.6/site-packages/pymysql/connections.py", line 325, in __init__
    self.connect()
  File "/home/frappe/frappe-bench/env/lib/python3.6/site-packages/pymysql/connections.py", line 630, in connect
    raise exc
pymysql.err.OperationalError: (2003, "Can't connect to MySQL server on 'localhost' ([Errno 111] Connection refused)")
[ERROR] 2021-03-25 11:44:27,755 | /home/frappe/frappe-bench/apps/frappe/frappe/utils/error.py:
New Exception collected with id: 2021-03-25 11:44:27.751978-10.0.2.2-860
[ERROR] 2021-03-25 11:45:16,431 | /home/frappe/frappe-bench/apps/frappe/frappe/app.py:
Site: site1.local
Request Error
Traceback (most recent call last):
  File "/home/frappe/frappe-bench/env/lib/python3.6/site-packages/pymysql/connections.py", line 583, in connect
    **kwargs)
  File "/usr/lib/python3.6/socket.py", line 724, in create_connection
    raise err
  File "/usr/lib/python3.6/socket.py", line 713, in create_connection
    sock.connect(sa)
ConnectionRefusedError: [Errno 111] Connection refused

During handling of the above exception, another exception occurred:

Traceback (most recent call last):
  File "/home/frappe/frappe-bench/apps/frappe/frappe/app.py", line 54, in application
    init_request(request)
  File "/home/frappe/frappe-bench/apps/frappe/frappe/app.py", line 126, in init_request
    frappe.local.http_request = frappe.auth.HTTPRequest()
  File "/home/frappe/frappe-bench/apps/frappe/frappe/auth.py", line 42, in __init__
    self.set_lang()
  File "/home/frappe/frappe-bench/apps/frappe/frappe/auth.py", line 86, in set_lang
    frappe.local.lang = guess_language()
  File "/home/frappe/frappe-bench/apps/frappe/frappe/translate.py", line 29, in guess_language
    lang_list = get_all_languages() or []
  File "/home/frappe/frappe-bench/apps/frappe/frappe/translate.py", line 85, in get_all_languages
    return frappe.cache().get_value('languages', _get)
  File "/home/frappe/frappe-bench/apps/frappe/frappe/utils/redis_wrapper.py", line 79, in get_value
    val = generator()
  File "/home/frappe/frappe-bench/apps/frappe/frappe/translate.py", line 84, in _get
    return frappe.db.sql_list('select name from tabLanguage')
  File "/home/frappe/frappe-bench/apps/frappe/frappe/database/database.py", line 236, in sql_list
    return [r[0] for r in self.sql(query, values, debug=debug)]
  File "/home/frappe/frappe-bench/apps/frappe/frappe/database/database.py", line 122, in sql
    self.connect()
  File "/home/frappe/frappe-bench/apps/frappe/frappe/database/database.py", line 75, in connect
    self._conn = self.get_connection()
  File "/home/frappe/frappe-bench/apps/frappe/frappe/database/mariadb/database.py", line 90, in get_connection
    local_infile = frappe.conf.local_infile)
  File "/home/frappe/frappe-bench/env/lib/python3.6/site-packages/pymysql/__init__.py", line 94, in Connect
    return Connection(*args, **kwargs)
  File "/home/frappe/frappe-bench/env/lib/python3.6/site-packages/pymysql/connections.py", line 325, in __init__
    self.connect()
  File "/home/frappe/frappe-bench/env/lib/python3.6/site-packages/pymysql/connections.py", line 630, in connect
    raise exc
pymysql.err.OperationalError: (2003, "Can't connect to MySQL server on 'localhost' ([Errno 111] Connection refused)")
[ERROR] 2021-03-25 11:45:16,436 | /home/frappe/frappe-bench/apps/frappe/frappe/utils/error.py:
New Exception collected with id: 2021-03-25 11:45:16.432051-10.0.2.2-97e
[ERROR] 2021-03-25 11:45:16,603 | /home/frappe/frappe-bench/apps/frappe/frappe/app.py:
Site: site1.local
Request Error
Traceback (most recent call last):
  File "/home/frappe/frappe-bench/env/lib/python3.6/site-packages/pymysql/connections.py", line 583, in connect
    **kwargs)
  File "/usr/lib/python3.6/socket.py", line 724, in create_connection
    raise err
  File "/usr/lib/python3.6/socket.py", line 713, in create_connection
    sock.connect(sa)
ConnectionRefusedError: [Errno 111] Connection refused

During handling of the above exception, another exception occurred:

Traceback (most recent call last):
  File "/home/frappe/frappe-bench/apps/frappe/frappe/app.py", line 54, in application
    init_request(request)
  File "/home/frappe/frappe-bench/apps/frappe/frappe/app.py", line 126, in init_request
    frappe.local.http_request = frappe.auth.HTTPRequest()
  File "/home/frappe/frappe-bench/apps/frappe/frappe/auth.py", line 42, in __init__
    self.set_lang()
  File "/home/frappe/frappe-bench/apps/frappe/frappe/auth.py", line 86, in set_lang
    frappe.local.lang = guess_language()
  File "/home/frappe/frappe-bench/apps/frappe/frappe/translate.py", line 29, in guess_language
    lang_list = get_all_languages() or []
  File "/home/frappe/frappe-bench/apps/frappe/frappe/translate.py", line 85, in get_all_languages
    return frappe.cache().get_value('languages', _get)
  File "/home/frappe/frappe-bench/apps/frappe/frappe/utils/redis_wrapper.py", line 79, in get_value
    val = generator()
  File "/home/frappe/frappe-bench/apps/frappe/frappe/translate.py", line 84, in _get
    return frappe.db.sql_list('select name from tabLanguage')
  File "/home/frappe/frappe-bench/apps/frappe/frappe/database/database.py", line 236, in sql_list
    return [r[0] for r in self.sql(query, values, debug=debug)]
  File "/home/frappe/frappe-bench/apps/frappe/frappe/database/database.py", line 122, in sql
    self.connect()
  File "/home/frappe/frappe-bench/apps/frappe/frappe/database/database.py", line 75, in connect
    self._conn = self.get_connection()
  File "/home/frappe/frappe-bench/apps/frappe/frappe/database/mariadb/database.py", line 90, in get_connection
    local_infile = frappe.conf.local_infile)
  File "/home/frappe/frappe-bench/env/lib/python3.6/site-packages/pymysql/__init__.py", line 94, in Connect
    return Connection(*args, **kwargs)
  File "/home/frappe/frappe-bench/env/lib/python3.6/site-packages/pymysql/connections.py", line 325, in __init__
    self.connect()
  File "/home/frappe/frappe-bench/env/lib/python3.6/site-packages/pymysql/connections.py", line 630, in connect
    raise exc
pymysql.err.OperationalError: (2003, "Can't connect to MySQL server on 'localhost' ([Errno 111] Connection refused)")
[ERROR] 2021-03-25 11:45:16,610 | /home/frappe/frappe-bench/apps/frappe/frappe/utils/error.py:
New Exception collected with id: 2021-03-25 11:45:16.604384-10.0.2.2-4cb
[ERROR] 2021-03-25 11:45:18,128 | /home/frappe/frappe-bench/apps/frappe/frappe/app.py:
Site: site1.local
Request Error
Traceback (most recent call last):
  File "/home/frappe/frappe-bench/env/lib/python3.6/site-packages/pymysql/connections.py", line 583, in connect
    **kwargs)
  File "/usr/lib/python3.6/socket.py", line 724, in create_connection
    raise err
  File "/usr/lib/python3.6/socket.py", line 713, in create_connection
    sock.connect(sa)
ConnectionRefusedError: [Errno 111] Connection refused

During handling of the above exception, another exception occurred:

Traceback (most recent call last):
  File "/home/frappe/frappe-bench/apps/frappe/frappe/app.py", line 54, in application
    init_request(request)
  File "/home/frappe/frappe-bench/apps/frappe/frappe/app.py", line 126, in init_request
    frappe.local.http_request = frappe.auth.HTTPRequest()
  File "/home/frappe/frappe-bench/apps/frappe/frappe/auth.py", line 42, in __init__
    self.set_lang()
  File "/home/frappe/frappe-bench/apps/frappe/frappe/auth.py", line 86, in set_lang
    frappe.local.lang = guess_language()
  File "/home/frappe/frappe-bench/apps/frappe/frappe/translate.py", line 29, in guess_language
    lang_list = get_all_languages() or []
  File "/home/frappe/frappe-bench/apps/frappe/frappe/translate.py", line 85, in get_all_languages
    return frappe.cache().get_value('languages', _get)
  File "/home/frappe/frappe-bench/apps/frappe/frappe/utils/redis_wrapper.py", line 79, in get_value
    val = generator()
  File "/home/frappe/frappe-bench/apps/frappe/frappe/translate.py", line 84, in _get
    return frappe.db.sql_list('select name from tabLanguage')
  File "/home/frappe/frappe-bench/apps/frappe/frappe/database/database.py", line 236, in sql_list
    return [r[0] for r in self.sql(query, values, debug=debug)]
  File "/home/frappe/frappe-bench/apps/frappe/frappe/database/database.py", line 122, in sql
    self.connect()
  File "/home/frappe/frappe-bench/apps/frappe/frappe/database/database.py", line 75, in connect
    self._conn = self.get_connection()
  File "/home/frappe/frappe-bench/apps/frappe/frappe/database/mariadb/database.py", line 90, in get_connection
    local_infile = frappe.conf.local_infile)
  File "/home/frappe/frappe-bench/env/lib/python3.6/site-packages/pymysql/__init__.py", line 94, in Connect
    return Connection(*args, **kwargs)
  File "/home/frappe/frappe-bench/env/lib/python3.6/site-packages/pymysql/connections.py", line 325, in __init__
    self.connect()
  File "/home/frappe/frappe-bench/env/lib/python3.6/site-packages/pymysql/connections.py", line 630, in connect
    raise exc
pymysql.err.OperationalError: (2003, "Can't connect to MySQL server on 'localhost' ([Errno 111] Connection refused)")
[ERROR] 2021-03-25 11:45:18,133 | /home/frappe/frappe-bench/apps/frappe/frappe/utils/error.py:
New Exception collected with id: 2021-03-25 11:45:18.129168-10.0.2.2-d38
[ERROR] 2021-03-25 11:45:18,244 | /home/frappe/frappe-bench/apps/frappe/frappe/app.py:
Site: site1.local
Request Error
Traceback (most recent call last):
  File "/home/frappe/frappe-bench/env/lib/python3.6/site-packages/pymysql/connections.py", line 583, in connect
    **kwargs)
  File "/usr/lib/python3.6/socket.py", line 724, in create_connection
    raise err
  File "/usr/lib/python3.6/socket.py", line 713, in create_connection
    sock.connect(sa)
ConnectionRefusedError: [Errno 111] Connection refused

During handling of the above exception, another exception occurred:

Traceback (most recent call last):
  File "/home/frappe/frappe-bench/apps/frappe/frappe/app.py", line 54, in application
    init_request(request)
  File "/home/frappe/frappe-bench/apps/frappe/frappe/app.py", line 126, in init_request
    frappe.local.http_request = frappe.auth.HTTPRequest()
  File "/home/frappe/frappe-bench/apps/frappe/frappe/auth.py", line 42, in __init__
    self.set_lang()
  File "/home/frappe/frappe-bench/apps/frappe/frappe/auth.py", line 86, in set_lang
    frappe.local.lang = guess_language()
  File "/home/frappe/frappe-bench/apps/frappe/frappe/translate.py", line 29, in guess_language
    lang_list = get_all_languages() or []
  File "/home/frappe/frappe-bench/apps/frappe/frappe/translate.py", line 85, in get_all_languages
    return frappe.cache().get_value('languages', _get)
  File "/home/frappe/frappe-bench/apps/frappe/frappe/utils/redis_wrapper.py", line 79, in get_value
    val = generator()
  File "/home/frappe/frappe-bench/apps/frappe/frappe/translate.py", line 84, in _get
    return frappe.db.sql_list('select name from tabLanguage')
  File "/home/frappe/frappe-bench/apps/frappe/frappe/database/database.py", line 236, in sql_list
    return [r[0] for r in self.sql(query, values, debug=debug)]
  File "/home/frappe/frappe-bench/apps/frappe/frappe/database/database.py", line 122, in sql
    self.connect()
  File "/home/frappe/frappe-bench/apps/frappe/frappe/database/database.py", line 75, in connect
    self._conn = self.get_connection()
  File "/home/frappe/frappe-bench/apps/frappe/frappe/database/mariadb/database.py", line 90, in get_connection
    local_infile = frappe.conf.local_infile)
  File "/home/frappe/frappe-bench/env/lib/python3.6/site-packages/pymysql/__init__.py", line 94, in Connect
    return Connection(*args, **kwargs)
  File "/home/frappe/frappe-bench/env/lib/python3.6/site-packages/pymysql/connections.py", line 325, in __init__
    self.connect()
  File "/home/frappe/frappe-bench/env/lib/python3.6/site-packages/pymysql/connections.py", line 630, in connect
    raise exc
pymysql.err.OperationalError: (2003, "Can't connect to MySQL server on 'localhost' ([Errno 111] Connection refused)")
[ERROR] 2021-03-25 11:45:18,248 | /home/frappe/frappe-bench/apps/frappe/frappe/utils/error.py:
New Exception collected with id: 2021-03-25 11:45:18.244741-10.0.2.2-499
[ERROR] 2021-03-25 11:45:21,906 | /home/frappe/frappe-bench/apps/frappe/frappe/utils/scheduler.py:
Site: site1.local
Exception in Enqueue Events for Site site1.local
Traceback (most recent call last):
  File "/home/frappe/frappe-bench/env/lib/python3.6/site-packages/pymysql/connections.py", line 583, in connect
    **kwargs)
  File "/usr/lib/python3.6/socket.py", line 724, in create_connection
    raise err
  File "/usr/lib/python3.6/socket.py", line 713, in create_connection
    sock.connect(sa)
ConnectionRefusedError: [Errno 111] Connection refused

During handling of the above exception, another exception occurred:

Traceback (most recent call last):
  File "/home/frappe/frappe-bench/apps/frappe/frappe/utils/scheduler.py", line 81, in enqueue_events_for_site
    if is_scheduler_inactive():
  File "/home/frappe/frappe-bench/apps/frappe/frappe/utils/scheduler.py", line 228, in is_scheduler_inactive
    if is_scheduler_disabled():
  File "/home/frappe/frappe-bench/apps/frappe/frappe/utils/scheduler.py", line 237, in is_scheduler_disabled
    return not frappe.utils.cint(frappe.db.get_single_value("System Settings", "enable_scheduler"))
  File "/home/frappe/frappe-bench/apps/frappe/frappe/database/database.py", line 553, in get_single_value
    `tabSingles` where `doctype`=%s and `field`=%s""", (doctype, fieldname))
  File "/home/frappe/frappe-bench/apps/frappe/frappe/database/database.py", line 122, in sql
    self.connect()
  File "/home/frappe/frappe-bench/apps/frappe/frappe/database/database.py", line 75, in connect
    self._conn = self.get_connection()
  File "/home/frappe/frappe-bench/apps/frappe/frappe/database/mariadb/database.py", line 90, in get_connection
    local_infile = frappe.conf.local_infile)
  File "/home/frappe/frappe-bench/env/lib/python3.6/site-packages/pymysql/__init__.py", line 94, in Connect
    return Connection(*args, **kwargs)
  File "/home/frappe/frappe-bench/env/lib/python3.6/site-packages/pymysql/connections.py", line 325, in __init__
    self.connect()
  File "/home/frappe/frappe-bench/env/lib/python3.6/site-packages/pymysql/connections.py", line 630, in connect
    raise exc
pymysql.err.OperationalError: (2003, "Can't connect to MySQL server on 'localhost' ([Errno 111] Connection refused)")

[ERROR] 2021-03-25 11:46:22,290 | /home/frappe/frappe-bench/apps/frappe/frappe/utils/scheduler.py:
Site: site1.local
Exception in Enqueue Events for Site site1.local
Traceback (most recent call last):
  File "/home/frappe/frappe-bench/env/lib/python3.6/site-packages/pymysql/connections.py", line 583, in connect
    **kwargs)
  File "/usr/lib/python3.6/socket.py", line 724, in create_connection
    raise err
  File "/usr/lib/python3.6/socket.py", line 713, in create_connection
    sock.connect(sa)
ConnectionRefusedError: [Errno 111] Connection refused

During handling of the above exception, another exception occurred:

Traceback (most recent call last):
  File "/home/frappe/frappe-bench/apps/frappe/frappe/utils/scheduler.py", line 81, in enqueue_events_for_site
    if is_scheduler_inactive():
  File "/home/frappe/frappe-bench/apps/frappe/frappe/utils/scheduler.py", line 228, in is_scheduler_inactive
    if is_scheduler_disabled():
  File "/home/frappe/frappe-bench/apps/frappe/frappe/utils/scheduler.py", line 237, in is_scheduler_disabled
    return not frappe.utils.cint(frappe.db.get_single_value("System Settings", "enable_scheduler"))
  File "/home/frappe/frappe-bench/apps/frappe/frappe/database/database.py", line 553, in get_single_value
    `tabSingles` where `doctype`=%s and `field`=%s""", (doctype, fieldname))
  File "/home/frappe/frappe-bench/apps/frappe/frappe/database/database.py", line 122, in sql
    self.connect()
  File "/home/frappe/frappe-bench/apps/frappe/frappe/database/database.py", line 75, in connect
    self._conn = self.get_connection()
  File "/home/frappe/frappe-bench/apps/frappe/frappe/database/mariadb/database.py", line 90, in get_connection
    local_infile = frappe.conf.local_infile)
  File "/home/frappe/frappe-bench/env/lib/python3.6/site-packages/pymysql/__init__.py", line 94, in Connect
    return Connection(*args, **kwargs)
  File "/home/frappe/frappe-bench/env/lib/python3.6/site-packages/pymysql/connections.py", line 325, in __init__
    self.connect()
  File "/home/frappe/frappe-bench/env/lib/python3.6/site-packages/pymysql/connections.py", line 630, in connect
    raise exc
pymysql.err.OperationalError: (2003, "Can't connect to MySQL server on 'localhost' ([Errno 111] Connection refused)")

[ERROR] 2021-03-25 11:49:57,509 | /home/frappe/frappe-bench/apps/frappe/frappe/utils/error.py:
New Exception collected with id: 2021-03-25 11:49:57.484113-10.0.2.2-f5a
[ERROR] 2021-03-25 11:49:57,698 | /home/frappe/frappe-bench/apps/frappe/frappe/utils/error.py:
New Exception collected with id: 2021-03-25 11:49:57.689096-10.0.2.2-149
[ERROR] 2021-03-25 11:52:31,821 | /home/frappe/frappe-bench/apps/frappe/frappe/utils/error.py:
New Exception collected with id: 2021-03-25 11:52:31.798556-10.0.2.2-a0c
