[ERROR] 2021-03-25 11:47:22,612 | /home/frappe/frappe-bench/apps/frappe/frappe/utils/scheduler.py:
Site: site1.local
Exception in Enqueue Events for Site site1.local
Traceback (most recent call last):
  File "/home/frappe/frappe-bench/env/lib/python3.6/site-packages/pymysql/connections.py", line 583, in connect
    **kwargs)
  File "/usr/lib/python3.6/socket.py", line 724, in create_connection
    raise err
  File "/usr/lib/python3.6/socket.py", line 713, in create_connection
    sock.connect(sa)
ConnectionRefusedError: [Errno 111] Connection refused

During handling of the above exception, another exception occurred:

Traceback (most recent call last):
  File "/home/frappe/frappe-bench/apps/frappe/frappe/utils/scheduler.py", line 81, in enqueue_events_for_site
    if is_scheduler_inactive():
  File "/home/frappe/frappe-bench/apps/frappe/frappe/utils/scheduler.py", line 228, in is_scheduler_inactive
    if is_scheduler_disabled():
  File "/home/frappe/frappe-bench/apps/frappe/frappe/utils/scheduler.py", line 237, in is_scheduler_disabled
    return not frappe.utils.cint(frappe.db.get_single_value("System Settings", "enable_scheduler"))
  File "/home/frappe/frappe-bench/apps/frappe/frappe/database/database.py", line 553, in get_single_value
    `tabSingles` where `doctype`=%s and `field`=%s""", (doctype, fieldname))
  File "/home/frappe/frappe-bench/apps/frappe/frappe/database/database.py", line 122, in sql
    self.connect()
  File "/home/frappe/frappe-bench/apps/frappe/frappe/database/database.py", line 75, in connect
    self._conn = self.get_connection()
  File "/home/frappe/frappe-bench/apps/frappe/frappe/database/mariadb/database.py", line 90, in get_connection
    local_infile = frappe.conf.local_infile)
  File "/home/frappe/frappe-bench/env/lib/python3.6/site-packages/pymysql/__init__.py", line 94, in Connect
    return Connection(*args, **kwargs)
  File "/home/frappe/frappe-bench/env/lib/python3.6/site-packages/pymysql/connections.py", line 325, in __init__
    self.connect()
  File "/home/frappe/frappe-bench/env/lib/python3.6/site-packages/pymysql/connections.py", line 630, in connect
    raise exc
pymysql.err.OperationalError: (2003, "Can't connect to MySQL server on 'localhost' ([Errno 111] Connection refused)")

[ERROR] 2021-03-25 11:48:23,009 | /home/frappe/frappe-bench/apps/frappe/frappe/utils/scheduler.py:
Site: site1.local
Exception in Enqueue Events for Site site1.local
Traceback (most recent call last):
  File "/home/frappe/frappe-bench/env/lib/python3.6/site-packages/pymysql/connections.py", line 583, in connect
    **kwargs)
  File "/usr/lib/python3.6/socket.py", line 724, in create_connection
    raise err
  File "/usr/lib/python3.6/socket.py", line 713, in create_connection
    sock.connect(sa)
ConnectionRefusedError: [Errno 111] Connection refused

During handling of the above exception, another exception occurred:

Traceback (most recent call last):
  File "/home/frappe/frappe-bench/apps/frappe/frappe/utils/scheduler.py", line 81, in enqueue_events_for_site
    if is_scheduler_inactive():
  File "/home/frappe/frappe-bench/apps/frappe/frappe/utils/scheduler.py", line 228, in is_scheduler_inactive
    if is_scheduler_disabled():
  File "/home/frappe/frappe-bench/apps/frappe/frappe/utils/scheduler.py", line 237, in is_scheduler_disabled
    return not frappe.utils.cint(frappe.db.get_single_value("System Settings", "enable_scheduler"))
  File "/home/frappe/frappe-bench/apps/frappe/frappe/database/database.py", line 553, in get_single_value
    `tabSingles` where `doctype`=%s and `field`=%s""", (doctype, fieldname))
  File "/home/frappe/frappe-bench/apps/frappe/frappe/database/database.py", line 122, in sql
    self.connect()
  File "/home/frappe/frappe-bench/apps/frappe/frappe/database/database.py", line 75, in connect
    self._conn = self.get_connection()
  File "/home/frappe/frappe-bench/apps/frappe/frappe/database/mariadb/database.py", line 90, in get_connection
    local_infile = frappe.conf.local_infile)
  File "/home/frappe/frappe-bench/env/lib/python3.6/site-packages/pymysql/__init__.py", line 94, in Connect
    return Connection(*args, **kwargs)
  File "/home/frappe/frappe-bench/env/lib/python3.6/site-packages/pymysql/connections.py", line 325, in __init__
    self.connect()
  File "/home/frappe/frappe-bench/env/lib/python3.6/site-packages/pymysql/connections.py", line 630, in connect
    raise exc
pymysql.err.OperationalError: (2003, "Can't connect to MySQL server on 'localhost' ([Errno 111] Connection refused)")

[ERROR] 2021-03-25 11:49:23,309 | /home/frappe/frappe-bench/apps/frappe/frappe/utils/scheduler.py:
Site: site1.local
Exception in Enqueue Events for Site site1.local
Traceback (most recent call last):
  File "/home/frappe/frappe-bench/env/lib/python3.6/site-packages/pymysql/connections.py", line 583, in connect
    **kwargs)
  File "/usr/lib/python3.6/socket.py", line 724, in create_connection
    raise err
  File "/usr/lib/python3.6/socket.py", line 713, in create_connection
    sock.connect(sa)
ConnectionRefusedError: [Errno 111] Connection refused

During handling of the above exception, another exception occurred:

Traceback (most recent call last):
  File "/home/frappe/frappe-bench/apps/frappe/frappe/utils/scheduler.py", line 81, in enqueue_events_for_site
    if is_scheduler_inactive():
  File "/home/frappe/frappe-bench/apps/frappe/frappe/utils/scheduler.py", line 228, in is_scheduler_inactive
    if is_scheduler_disabled():
  File "/home/frappe/frappe-bench/apps/frappe/frappe/utils/scheduler.py", line 237, in is_scheduler_disabled
    return not frappe.utils.cint(frappe.db.get_single_value("System Settings", "enable_scheduler"))
  File "/home/frappe/frappe-bench/apps/frappe/frappe/database/database.py", line 553, in get_single_value
    `tabSingles` where `doctype`=%s and `field`=%s""", (doctype, fieldname))
  File "/home/frappe/frappe-bench/apps/frappe/frappe/database/database.py", line 122, in sql
    self.connect()
  File "/home/frappe/frappe-bench/apps/frappe/frappe/database/database.py", line 75, in connect
    self._conn = self.get_connection()
  File "/home/frappe/frappe-bench/apps/frappe/frappe/database/mariadb/database.py", line 90, in get_connection
    local_infile = frappe.conf.local_infile)
  File "/home/frappe/frappe-bench/env/lib/python3.6/site-packages/pymysql/__init__.py", line 94, in Connect
    return Connection(*args, **kwargs)
  File "/home/frappe/frappe-bench/env/lib/python3.6/site-packages/pymysql/connections.py", line 325, in __init__
    self.connect()
  File "/home/frappe/frappe-bench/env/lib/python3.6/site-packages/pymysql/connections.py", line 630, in connect
    raise exc
pymysql.err.OperationalError: (2003, "Can't connect to MySQL server on 'localhost' ([Errno 111] Connection refused)")

[ERROR] 2021-03-25 11:50:23,453 | /home/frappe/frappe-bench/apps/frappe/frappe/utils/scheduler.py:
Site: site1.local
Exception in Enqueue Events for Site site1.local
Traceback (most recent call last):
  File "/home/frappe/frappe-bench/env/lib/python3.6/site-packages/pymysql/connections.py", line 583, in connect
    **kwargs)
  File "/usr/lib/python3.6/socket.py", line 724, in create_connection
    raise err
  File "/usr/lib/python3.6/socket.py", line 713, in create_connection
    sock.connect(sa)
ConnectionRefusedError: [Errno 111] Connection refused

During handling of the above exception, another exception occurred:

Traceback (most recent call last):
  File "/home/frappe/frappe-bench/apps/frappe/frappe/utils/scheduler.py", line 81, in enqueue_events_for_site
    if is_scheduler_inactive():
  File "/home/frappe/frappe-bench/apps/frappe/frappe/utils/scheduler.py", line 228, in is_scheduler_inactive
    if is_scheduler_disabled():
  File "/home/frappe/frappe-bench/apps/frappe/frappe/utils/scheduler.py", line 237, in is_scheduler_disabled
    return not frappe.utils.cint(frappe.db.get_single_value("System Settings", "enable_scheduler"))
  File "/home/frappe/frappe-bench/apps/frappe/frappe/database/database.py", line 553, in get_single_value
    `tabSingles` where `doctype`=%s and `field`=%s""", (doctype, fieldname))
  File "/home/frappe/frappe-bench/apps/frappe/frappe/database/database.py", line 122, in sql
    self.connect()
  File "/home/frappe/frappe-bench/apps/frappe/frappe/database/database.py", line 75, in connect
    self._conn = self.get_connection()
  File "/home/frappe/frappe-bench/apps/frappe/frappe/database/mariadb/database.py", line 90, in get_connection
    local_infile = frappe.conf.local_infile)
  File "/home/frappe/frappe-bench/env/lib/python3.6/site-packages/pymysql/__init__.py", line 94, in Connect
    return Connection(*args, **kwargs)
  File "/home/frappe/frappe-bench/env/lib/python3.6/site-packages/pymysql/connections.py", line 325, in __init__
    self.connect()
  File "/home/frappe/frappe-bench/env/lib/python3.6/site-packages/pymysql/connections.py", line 630, in connect
    raise exc
pymysql.err.OperationalError: (2003, "Can't connect to MySQL server on 'localhost' ([Errno 111] Connection refused)")

[ERROR] 2021-03-25 11:51:23,583 | /home/frappe/frappe-bench/apps/frappe/frappe/utils/scheduler.py:
Site: site1.local
Exception in Enqueue Events for Site site1.local
Traceback (most recent call last):
  File "/home/frappe/frappe-bench/env/lib/python3.6/site-packages/pymysql/connections.py", line 583, in connect
    **kwargs)
  File "/usr/lib/python3.6/socket.py", line 724, in create_connection
    raise err
  File "/usr/lib/python3.6/socket.py", line 713, in create_connection
    sock.connect(sa)
ConnectionRefusedError: [Errno 111] Connection refused

During handling of the above exception, another exception occurred:

Traceback (most recent call last):
  File "/home/frappe/frappe-bench/apps/frappe/frappe/utils/scheduler.py", line 81, in enqueue_events_for_site
    if is_scheduler_inactive():
  File "/home/frappe/frappe-bench/apps/frappe/frappe/utils/scheduler.py", line 228, in is_scheduler_inactive
    if is_scheduler_disabled():
  File "/home/frappe/frappe-bench/apps/frappe/frappe/utils/scheduler.py", line 237, in is_scheduler_disabled
    return not frappe.utils.cint(frappe.db.get_single_value("System Settings", "enable_scheduler"))
  File "/home/frappe/frappe-bench/apps/frappe/frappe/database/database.py", line 553, in get_single_value
    `tabSingles` where `doctype`=%s and `field`=%s""", (doctype, fieldname))
  File "/home/frappe/frappe-bench/apps/frappe/frappe/database/database.py", line 122, in sql
    self.connect()
  File "/home/frappe/frappe-bench/apps/frappe/frappe/database/database.py", line 75, in connect
    self._conn = self.get_connection()
  File "/home/frappe/frappe-bench/apps/frappe/frappe/database/mariadb/database.py", line 90, in get_connection
    local_infile = frappe.conf.local_infile)
  File "/home/frappe/frappe-bench/env/lib/python3.6/site-packages/pymysql/__init__.py", line 94, in Connect
    return Connection(*args, **kwargs)
  File "/home/frappe/frappe-bench/env/lib/python3.6/site-packages/pymysql/connections.py", line 325, in __init__
    self.connect()
  File "/home/frappe/frappe-bench/env/lib/python3.6/site-packages/pymysql/connections.py", line 630, in connect
    raise exc
pymysql.err.OperationalError: (2003, "Can't connect to MySQL server on 'localhost' ([Errno 111] Connection refused)")

[ERROR] 2021-03-25 11:52:23,910 | /home/frappe/frappe-bench/apps/frappe/frappe/utils/scheduler.py:
Site: site1.local
Exception in Enqueue Events for Site site1.local
Traceback (most recent call last):
  File "/home/frappe/frappe-bench/env/lib/python3.6/site-packages/pymysql/connections.py", line 583, in connect
    **kwargs)
  File "/usr/lib/python3.6/socket.py", line 724, in create_connection
    raise err
  File "/usr/lib/python3.6/socket.py", line 713, in create_connection
    sock.connect(sa)
ConnectionRefusedError: [Errno 111] Connection refused

During handling of the above exception, another exception occurred:

Traceback (most recent call last):
  File "/home/frappe/frappe-bench/apps/frappe/frappe/utils/scheduler.py", line 81, in enqueue_events_for_site
    if is_scheduler_inactive():
  File "/home/frappe/frappe-bench/apps/frappe/frappe/utils/scheduler.py", line 228, in is_scheduler_inactive
    if is_scheduler_disabled():
  File "/home/frappe/frappe-bench/apps/frappe/frappe/utils/scheduler.py", line 237, in is_scheduler_disabled
    return not frappe.utils.cint(frappe.db.get_single_value("System Settings", "enable_scheduler"))
  File "/home/frappe/frappe-bench/apps/frappe/frappe/database/database.py", line 553, in get_single_value
    `tabSingles` where `doctype`=%s and `field`=%s""", (doctype, fieldname))
  File "/home/frappe/frappe-bench/apps/frappe/frappe/database/database.py", line 122, in sql
    self.connect()
  File "/home/frappe/frappe-bench/apps/frappe/frappe/database/database.py", line 75, in connect
    self._conn = self.get_connection()
  File "/home/frappe/frappe-bench/apps/frappe/frappe/database/mariadb/database.py", line 90, in get_connection
    local_infile = frappe.conf.local_infile)
  File "/home/frappe/frappe-bench/env/lib/python3.6/site-packages/pymysql/__init__.py", line 94, in Connect
    return Connection(*args, **kwargs)
  File "/home/frappe/frappe-bench/env/lib/python3.6/site-packages/pymysql/connections.py", line 325, in __init__
    self.connect()
  File "/home/frappe/frappe-bench/env/lib/python3.6/site-packages/pymysql/connections.py", line 630, in connect
    raise exc
pymysql.err.OperationalError: (2003, "Can't connect to MySQL server on 'localhost' ([Errno 111] Connection refused)")

[ERROR] 2021-03-25 11:53:24,123 | /home/frappe/frappe-bench/apps/frappe/frappe/utils/scheduler.py:
Site: site1.local
Exception in Enqueue Events for Site site1.local
Traceback (most recent call last):
  File "/home/frappe/frappe-bench/env/lib/python3.6/site-packages/pymysql/connections.py", line 583, in connect
    **kwargs)
  File "/usr/lib/python3.6/socket.py", line 724, in create_connection
    raise err
  File "/usr/lib/python3.6/socket.py", line 713, in create_connection
    sock.connect(sa)
ConnectionRefusedError: [Errno 111] Connection refused

During handling of the above exception, another exception occurred:

Traceback (most recent call last):
  File "/home/frappe/frappe-bench/apps/frappe/frappe/utils/scheduler.py", line 81, in enqueue_events_for_site
    if is_scheduler_inactive():
  File "/home/frappe/frappe-bench/apps/frappe/frappe/utils/scheduler.py", line 228, in is_scheduler_inactive
    if is_scheduler_disabled():
  File "/home/frappe/frappe-bench/apps/frappe/frappe/utils/scheduler.py", line 237, in is_scheduler_disabled
    return not frappe.utils.cint(frappe.db.get_single_value("System Settings", "enable_scheduler"))
  File "/home/frappe/frappe-bench/apps/frappe/frappe/database/database.py", line 553, in get_single_value
    `tabSingles` where `doctype`=%s and `field`=%s""", (doctype, fieldname))
  File "/home/frappe/frappe-bench/apps/frappe/frappe/database/database.py", line 122, in sql
    self.connect()
  File "/home/frappe/frappe-bench/apps/frappe/frappe/database/database.py", line 75, in connect
    self._conn = self.get_connection()
  File "/home/frappe/frappe-bench/apps/frappe/frappe/database/mariadb/database.py", line 90, in get_connection
    local_infile = frappe.conf.local_infile)
  File "/home/frappe/frappe-bench/env/lib/python3.6/site-packages/pymysql/__init__.py", line 94, in Connect
    return Connection(*args, **kwargs)
  File "/home/frappe/frappe-bench/env/lib/python3.6/site-packages/pymysql/connections.py", line 325, in __init__
    self.connect()
  File "/home/frappe/frappe-bench/env/lib/python3.6/site-packages/pymysql/connections.py", line 630, in connect
    raise exc
pymysql.err.OperationalError: (2003, "Can't connect to MySQL server on 'localhost' ([Errno 111] Connection refused)")

[ERROR] 2021-03-25 11:54:24,327 | /home/frappe/frappe-bench/apps/frappe/frappe/utils/scheduler.py:
Site: site1.local
Exception in Enqueue Events for Site site1.local
Traceback (most recent call last):
  File "/home/frappe/frappe-bench/env/lib/python3.6/site-packages/pymysql/connections.py", line 583, in connect
    **kwargs)
  File "/usr/lib/python3.6/socket.py", line 724, in create_connection
    raise err
  File "/usr/lib/python3.6/socket.py", line 713, in create_connection
    sock.connect(sa)
ConnectionRefusedError: [Errno 111] Connection refused

During handling of the above exception, another exception occurred:

Traceback (most recent call last):
  File "/home/frappe/frappe-bench/apps/frappe/frappe/utils/scheduler.py", line 81, in enqueue_events_for_site
    if is_scheduler_inactive():
  File "/home/frappe/frappe-bench/apps/frappe/frappe/utils/scheduler.py", line 228, in is_scheduler_inactive
    if is_scheduler_disabled():
  File "/home/frappe/frappe-bench/apps/frappe/frappe/utils/scheduler.py", line 237, in is_scheduler_disabled
    return not frappe.utils.cint(frappe.db.get_single_value("System Settings", "enable_scheduler"))
  File "/home/frappe/frappe-bench/apps/frappe/frappe/database/database.py", line 553, in get_single_value
    `tabSingles` where `doctype`=%s and `field`=%s""", (doctype, fieldname))
  File "/home/frappe/frappe-bench/apps/frappe/frappe/database/database.py", line 122, in sql
    self.connect()
  File "/home/frappe/frappe-bench/apps/frappe/frappe/database/database.py", line 75, in connect
    self._conn = self.get_connection()
  File "/home/frappe/frappe-bench/apps/frappe/frappe/database/mariadb/database.py", line 90, in get_connection
    local_infile = frappe.conf.local_infile)
  File "/home/frappe/frappe-bench/env/lib/python3.6/site-packages/pymysql/__init__.py", line 94, in Connect
    return Connection(*args, **kwargs)
  File "/home/frappe/frappe-bench/env/lib/python3.6/site-packages/pymysql/connections.py", line 325, in __init__
    self.connect()
  File "/home/frappe/frappe-bench/env/lib/python3.6/site-packages/pymysql/connections.py", line 630, in connect
    raise exc
pymysql.err.OperationalError: (2003, "Can't connect to MySQL server on 'localhost' ([Errno 111] Connection refused)")

[ERROR] 2021-03-25 11:55:24,602 | /home/frappe/frappe-bench/apps/frappe/frappe/utils/scheduler.py:
Site: site1.local
Exception in Enqueue Events for Site site1.local
Traceback (most recent call last):
  File "/home/frappe/frappe-bench/env/lib/python3.6/site-packages/pymysql/connections.py", line 583, in connect
    **kwargs)
  File "/usr/lib/python3.6/socket.py", line 724, in create_connection
    raise err
  File "/usr/lib/python3.6/socket.py", line 713, in create_connection
    sock.connect(sa)
ConnectionRefusedError: [Errno 111] Connection refused

During handling of the above exception, another exception occurred:

Traceback (most recent call last):
  File "/home/frappe/frappe-bench/apps/frappe/frappe/utils/scheduler.py", line 81, in enqueue_events_for_site
    if is_scheduler_inactive():
  File "/home/frappe/frappe-bench/apps/frappe/frappe/utils/scheduler.py", line 228, in is_scheduler_inactive
    if is_scheduler_disabled():
  File "/home/frappe/frappe-bench/apps/frappe/frappe/utils/scheduler.py", line 237, in is_scheduler_disabled
    return not frappe.utils.cint(frappe.db.get_single_value("System Settings", "enable_scheduler"))
  File "/home/frappe/frappe-bench/apps/frappe/frappe/database/database.py", line 553, in get_single_value
    `tabSingles` where `doctype`=%s and `field`=%s""", (doctype, fieldname))
  File "/home/frappe/frappe-bench/apps/frappe/frappe/database/database.py", line 122, in sql
    self.connect()
  File "/home/frappe/frappe-bench/apps/frappe/frappe/database/database.py", line 75, in connect
    self._conn = self.get_connection()
  File "/home/frappe/frappe-bench/apps/frappe/frappe/database/mariadb/database.py", line 90, in get_connection
    local_infile = frappe.conf.local_infile)
  File "/home/frappe/frappe-bench/env/lib/python3.6/site-packages/pymysql/__init__.py", line 94, in Connect
    return Connection(*args, **kwargs)
  File "/home/frappe/frappe-bench/env/lib/python3.6/site-packages/pymysql/connections.py", line 325, in __init__
    self.connect()
  File "/home/frappe/frappe-bench/env/lib/python3.6/site-packages/pymysql/connections.py", line 630, in connect
    raise exc
pymysql.err.OperationalError: (2003, "Can't connect to MySQL server on 'localhost' ([Errno 111] Connection refused)")

[ERROR] 2021-03-25 11:56:24,867 | /home/frappe/frappe-bench/apps/frappe/frappe/utils/scheduler.py:
Site: site1.local
Exception in Enqueue Events for Site site1.local
Traceback (most recent call last):
  File "/home/frappe/frappe-bench/env/lib/python3.6/site-packages/pymysql/connections.py", line 583, in connect
    **kwargs)
  File "/usr/lib/python3.6/socket.py", line 724, in create_connection
    raise err
  File "/usr/lib/python3.6/socket.py", line 713, in create_connection
    sock.connect(sa)
ConnectionRefusedError: [Errno 111] Connection refused

During handling of the above exception, another exception occurred:

Traceback (most recent call last):
  File "/home/frappe/frappe-bench/apps/frappe/frappe/utils/scheduler.py", line 81, in enqueue_events_for_site
    if is_scheduler_inactive():
  File "/home/frappe/frappe-bench/apps/frappe/frappe/utils/scheduler.py", line 228, in is_scheduler_inactive
    if is_scheduler_disabled():
  File "/home/frappe/frappe-bench/apps/frappe/frappe/utils/scheduler.py", line 237, in is_scheduler_disabled
    return not frappe.utils.cint(frappe.db.get_single_value("System Settings", "enable_scheduler"))
  File "/home/frappe/frappe-bench/apps/frappe/frappe/database/database.py", line 553, in get_single_value
    `tabSingles` where `doctype`=%s and `field`=%s""", (doctype, fieldname))
  File "/home/frappe/frappe-bench/apps/frappe/frappe/database/database.py", line 122, in sql
    self.connect()
  File "/home/frappe/frappe-bench/apps/frappe/frappe/database/database.py", line 75, in connect
    self._conn = self.get_connection()
  File "/home/frappe/frappe-bench/apps/frappe/frappe/database/mariadb/database.py", line 90, in get_connection
    local_infile = frappe.conf.local_infile)
  File "/home/frappe/frappe-bench/env/lib/python3.6/site-packages/pymysql/__init__.py", line 94, in Connect
    return Connection(*args, **kwargs)
  File "/home/frappe/frappe-bench/env/lib/python3.6/site-packages/pymysql/connections.py", line 325, in __init__
    self.connect()
  File "/home/frappe/frappe-bench/env/lib/python3.6/site-packages/pymysql/connections.py", line 630, in connect
    raise exc
pymysql.err.OperationalError: (2003, "Can't connect to MySQL server on 'localhost' ([Errno 111] Connection refused)")

[ERROR] 2021-03-25 11:57:25,077 | /home/frappe/frappe-bench/apps/frappe/frappe/utils/scheduler.py:
Site: site1.local
Exception in Enqueue Events for Site site1.local
Traceback (most recent call last):
  File "/home/frappe/frappe-bench/env/lib/python3.6/site-packages/pymysql/connections.py", line 583, in connect
    **kwargs)
  File "/usr/lib/python3.6/socket.py", line 724, in create_connection
    raise err
  File "/usr/lib/python3.6/socket.py", line 713, in create_connection
    sock.connect(sa)
ConnectionRefusedError: [Errno 111] Connection refused

During handling of the above exception, another exception occurred:

Traceback (most recent call last):
  File "/home/frappe/frappe-bench/apps/frappe/frappe/utils/scheduler.py", line 81, in enqueue_events_for_site
    if is_scheduler_inactive():
  File "/home/frappe/frappe-bench/apps/frappe/frappe/utils/scheduler.py", line 228, in is_scheduler_inactive
    if is_scheduler_disabled():
  File "/home/frappe/frappe-bench/apps/frappe/frappe/utils/scheduler.py", line 237, in is_scheduler_disabled
    return not frappe.utils.cint(frappe.db.get_single_value("System Settings", "enable_scheduler"))
  File "/home/frappe/frappe-bench/apps/frappe/frappe/database/database.py", line 553, in get_single_value
    `tabSingles` where `doctype`=%s and `field`=%s""", (doctype, fieldname))
  File "/home/frappe/frappe-bench/apps/frappe/frappe/database/database.py", line 122, in sql
    self.connect()
  File "/home/frappe/frappe-bench/apps/frappe/frappe/database/database.py", line 75, in connect
    self._conn = self.get_connection()
  File "/home/frappe/frappe-bench/apps/frappe/frappe/database/mariadb/database.py", line 90, in get_connection
    local_infile = frappe.conf.local_infile)
  File "/home/frappe/frappe-bench/env/lib/python3.6/site-packages/pymysql/__init__.py", line 94, in Connect
    return Connection(*args, **kwargs)
  File "/home/frappe/frappe-bench/env/lib/python3.6/site-packages/pymysql/connections.py", line 325, in __init__
    self.connect()
  File "/home/frappe/frappe-bench/env/lib/python3.6/site-packages/pymysql/connections.py", line 630, in connect
    raise exc
pymysql.err.OperationalError: (2003, "Can't connect to MySQL server on 'localhost' ([Errno 111] Connection refused)")

[ERROR] 2021-03-25 11:58:25,348 | /home/frappe/frappe-bench/apps/frappe/frappe/utils/scheduler.py:
Site: site1.local
Exception in Enqueue Events for Site site1.local
Traceback (most recent call last):
  File "/home/frappe/frappe-bench/env/lib/python3.6/site-packages/pymysql/connections.py", line 583, in connect
    **kwargs)
  File "/usr/lib/python3.6/socket.py", line 724, in create_connection
    raise err
  File "/usr/lib/python3.6/socket.py", line 713, in create_connection
    sock.connect(sa)
ConnectionRefusedError: [Errno 111] Connection refused

During handling of the above exception, another exception occurred:

Traceback (most recent call last):
  File "/home/frappe/frappe-bench/apps/frappe/frappe/utils/scheduler.py", line 81, in enqueue_events_for_site
    if is_scheduler_inactive():
  File "/home/frappe/frappe-bench/apps/frappe/frappe/utils/scheduler.py", line 228, in is_scheduler_inactive
    if is_scheduler_disabled():
  File "/home/frappe/frappe-bench/apps/frappe/frappe/utils/scheduler.py", line 237, in is_scheduler_disabled
    return not frappe.utils.cint(frappe.db.get_single_value("System Settings", "enable_scheduler"))
  File "/home/frappe/frappe-bench/apps/frappe/frappe/database/database.py", line 553, in get_single_value
    `tabSingles` where `doctype`=%s and `field`=%s""", (doctype, fieldname))
  File "/home/frappe/frappe-bench/apps/frappe/frappe/database/database.py", line 122, in sql
    self.connect()
  File "/home/frappe/frappe-bench/apps/frappe/frappe/database/database.py", line 75, in connect
    self._conn = self.get_connection()
  File "/home/frappe/frappe-bench/apps/frappe/frappe/database/mariadb/database.py", line 90, in get_connection
    local_infile = frappe.conf.local_infile)
  File "/home/frappe/frappe-bench/env/lib/python3.6/site-packages/pymysql/__init__.py", line 94, in Connect
    return Connection(*args, **kwargs)
  File "/home/frappe/frappe-bench/env/lib/python3.6/site-packages/pymysql/connections.py", line 325, in __init__
    self.connect()
  File "/home/frappe/frappe-bench/env/lib/python3.6/site-packages/pymysql/connections.py", line 630, in connect
    raise exc
pymysql.err.OperationalError: (2003, "Can't connect to MySQL server on 'localhost' ([Errno 111] Connection refused)")

[ERROR] 2021-03-25 11:59:25,551 | /home/frappe/frappe-bench/apps/frappe/frappe/utils/scheduler.py:
Site: site1.local
Exception in Enqueue Events for Site site1.local
Traceback (most recent call last):
  File "/home/frappe/frappe-bench/env/lib/python3.6/site-packages/pymysql/connections.py", line 583, in connect
    **kwargs)
  File "/usr/lib/python3.6/socket.py", line 724, in create_connection
    raise err
  File "/usr/lib/python3.6/socket.py", line 713, in create_connection
    sock.connect(sa)
ConnectionRefusedError: [Errno 111] Connection refused

During handling of the above exception, another exception occurred:

Traceback (most recent call last):
  File "/home/frappe/frappe-bench/apps/frappe/frappe/utils/scheduler.py", line 81, in enqueue_events_for_site
    if is_scheduler_inactive():
  File "/home/frappe/frappe-bench/apps/frappe/frappe/utils/scheduler.py", line 228, in is_scheduler_inactive
    if is_scheduler_disabled():
  File "/home/frappe/frappe-bench/apps/frappe/frappe/utils/scheduler.py", line 237, in is_scheduler_disabled
    return not frappe.utils.cint(frappe.db.get_single_value("System Settings", "enable_scheduler"))
  File "/home/frappe/frappe-bench/apps/frappe/frappe/database/database.py", line 553, in get_single_value
    `tabSingles` where `doctype`=%s and `field`=%s""", (doctype, fieldname))
  File "/home/frappe/frappe-bench/apps/frappe/frappe/database/database.py", line 122, in sql
    self.connect()
  File "/home/frappe/frappe-bench/apps/frappe/frappe/database/database.py", line 75, in connect
    self._conn = self.get_connection()
  File "/home/frappe/frappe-bench/apps/frappe/frappe/database/mariadb/database.py", line 90, in get_connection
    local_infile = frappe.conf.local_infile)
  File "/home/frappe/frappe-bench/env/lib/python3.6/site-packages/pymysql/__init__.py", line 94, in Connect
    return Connection(*args, **kwargs)
  File "/home/frappe/frappe-bench/env/lib/python3.6/site-packages/pymysql/connections.py", line 325, in __init__
    self.connect()
  File "/home/frappe/frappe-bench/env/lib/python3.6/site-packages/pymysql/connections.py", line 630, in connect
    raise exc
pymysql.err.OperationalError: (2003, "Can't connect to MySQL server on 'localhost' ([Errno 111] Connection refused)")

[ERROR] 2021-03-25 12:00:25,743 | /home/frappe/frappe-bench/apps/frappe/frappe/utils/scheduler.py:
Site: site1.local
Exception in Enqueue Events for Site site1.local
Traceback (most recent call last):
  File "/home/frappe/frappe-bench/env/lib/python3.6/site-packages/pymysql/connections.py", line 583, in connect
    **kwargs)
  File "/usr/lib/python3.6/socket.py", line 724, in create_connection
    raise err
  File "/usr/lib/python3.6/socket.py", line 713, in create_connection
    sock.connect(sa)
ConnectionRefusedError: [Errno 111] Connection refused

During handling of the above exception, another exception occurred:

Traceback (most recent call last):
  File "/home/frappe/frappe-bench/apps/frappe/frappe/utils/scheduler.py", line 81, in enqueue_events_for_site
    if is_scheduler_inactive():
  File "/home/frappe/frappe-bench/apps/frappe/frappe/utils/scheduler.py", line 228, in is_scheduler_inactive
    if is_scheduler_disabled():
  File "/home/frappe/frappe-bench/apps/frappe/frappe/utils/scheduler.py", line 237, in is_scheduler_disabled
    return not frappe.utils.cint(frappe.db.get_single_value("System Settings", "enable_scheduler"))
  File "/home/frappe/frappe-bench/apps/frappe/frappe/database/database.py", line 553, in get_single_value
    `tabSingles` where `doctype`=%s and `field`=%s""", (doctype, fieldname))
  File "/home/frappe/frappe-bench/apps/frappe/frappe/database/database.py", line 122, in sql
    self.connect()
  File "/home/frappe/frappe-bench/apps/frappe/frappe/database/database.py", line 75, in connect
    self._conn = self.get_connection()
  File "/home/frappe/frappe-bench/apps/frappe/frappe/database/mariadb/database.py", line 90, in get_connection
    local_infile = frappe.conf.local_infile)
  File "/home/frappe/frappe-bench/env/lib/python3.6/site-packages/pymysql/__init__.py", line 94, in Connect
    return Connection(*args, **kwargs)
  File "/home/frappe/frappe-bench/env/lib/python3.6/site-packages/pymysql/connections.py", line 325, in __init__
    self.connect()
  File "/home/frappe/frappe-bench/env/lib/python3.6/site-packages/pymysql/connections.py", line 630, in connect
    raise exc
pymysql.err.OperationalError: (2003, "Can't connect to MySQL server on 'localhost' ([Errno 111] Connection refused)")

[ERROR] 2021-03-25 12:01:25,986 | /home/frappe/frappe-bench/apps/frappe/frappe/utils/scheduler.py:
Site: site1.local
Exception in Enqueue Events for Site site1.local
Traceback (most recent call last):
  File "/home/frappe/frappe-bench/env/lib/python3.6/site-packages/pymysql/connections.py", line 583, in connect
    **kwargs)
  File "/usr/lib/python3.6/socket.py", line 724, in create_connection
    raise err
  File "/usr/lib/python3.6/socket.py", line 713, in create_connection
    sock.connect(sa)
ConnectionRefusedError: [Errno 111] Connection refused

During handling of the above exception, another exception occurred:

Traceback (most recent call last):
  File "/home/frappe/frappe-bench/apps/frappe/frappe/utils/scheduler.py", line 81, in enqueue_events_for_site
    if is_scheduler_inactive():
  File "/home/frappe/frappe-bench/apps/frappe/frappe/utils/scheduler.py", line 228, in is_scheduler_inactive
    if is_scheduler_disabled():
  File "/home/frappe/frappe-bench/apps/frappe/frappe/utils/scheduler.py", line 237, in is_scheduler_disabled
    return not frappe.utils.cint(frappe.db.get_single_value("System Settings", "enable_scheduler"))
  File "/home/frappe/frappe-bench/apps/frappe/frappe/database/database.py", line 553, in get_single_value
    `tabSingles` where `doctype`=%s and `field`=%s""", (doctype, fieldname))
  File "/home/frappe/frappe-bench/apps/frappe/frappe/database/database.py", line 122, in sql
    self.connect()
  File "/home/frappe/frappe-bench/apps/frappe/frappe/database/database.py", line 75, in connect
    self._conn = self.get_connection()
  File "/home/frappe/frappe-bench/apps/frappe/frappe/database/mariadb/database.py", line 90, in get_connection
    local_infile = frappe.conf.local_infile)
  File "/home/frappe/frappe-bench/env/lib/python3.6/site-packages/pymysql/__init__.py", line 94, in Connect
    return Connection(*args, **kwargs)
  File "/home/frappe/frappe-bench/env/lib/python3.6/site-packages/pymysql/connections.py", line 325, in __init__
    self.connect()
  File "/home/frappe/frappe-bench/env/lib/python3.6/site-packages/pymysql/connections.py", line 630, in connect
    raise exc
pymysql.err.OperationalError: (2003, "Can't connect to MySQL server on 'localhost' ([Errno 111] Connection refused)")

[ERROR] 2021-03-25 12:02:26,149 | /home/frappe/frappe-bench/apps/frappe/frappe/utils/scheduler.py:
Site: site1.local
Exception in Enqueue Events for Site site1.local
Traceback (most recent call last):
  File "/home/frappe/frappe-bench/env/lib/python3.6/site-packages/pymysql/connections.py", line 583, in connect
    **kwargs)
  File "/usr/lib/python3.6/socket.py", line 724, in create_connection
    raise err
  File "/usr/lib/python3.6/socket.py", line 713, in create_connection
    sock.connect(sa)
ConnectionRefusedError: [Errno 111] Connection refused

During handling of the above exception, another exception occurred:

Traceback (most recent call last):
  File "/home/frappe/frappe-bench/apps/frappe/frappe/utils/scheduler.py", line 81, in enqueue_events_for_site
    if is_scheduler_inactive():
  File "/home/frappe/frappe-bench/apps/frappe/frappe/utils/scheduler.py", line 228, in is_scheduler_inactive
    if is_scheduler_disabled():
  File "/home/frappe/frappe-bench/apps/frappe/frappe/utils/scheduler.py", line 237, in is_scheduler_disabled
    return not frappe.utils.cint(frappe.db.get_single_value("System Settings", "enable_scheduler"))
  File "/home/frappe/frappe-bench/apps/frappe/frappe/database/database.py", line 553, in get_single_value
    `tabSingles` where `doctype`=%s and `field`=%s""", (doctype, fieldname))
  File "/home/frappe/frappe-bench/apps/frappe/frappe/database/database.py", line 122, in sql
    self.connect()
  File "/home/frappe/frappe-bench/apps/frappe/frappe/database/database.py", line 75, in connect
    self._conn = self.get_connection()
  File "/home/frappe/frappe-bench/apps/frappe/frappe/database/mariadb/database.py", line 90, in get_connection
    local_infile = frappe.conf.local_infile)
  File "/home/frappe/frappe-bench/env/lib/python3.6/site-packages/pymysql/__init__.py", line 94, in Connect
    return Connection(*args, **kwargs)
  File "/home/frappe/frappe-bench/env/lib/python3.6/site-packages/pymysql/connections.py", line 325, in __init__
    self.connect()
  File "/home/frappe/frappe-bench/env/lib/python3.6/site-packages/pymysql/connections.py", line 630, in connect
    raise exc
pymysql.err.OperationalError: (2003, "Can't connect to MySQL server on 'localhost' ([Errno 111] Connection refused)")

[ERROR] 2021-03-25 12:03:26,527 | /home/frappe/frappe-bench/apps/frappe/frappe/utils/scheduler.py:
Site: site1.local
Exception in Enqueue Events for Site site1.local
Traceback (most recent call last):
  File "/home/frappe/frappe-bench/env/lib/python3.6/site-packages/pymysql/connections.py", line 583, in connect
    **kwargs)
  File "/usr/lib/python3.6/socket.py", line 724, in create_connection
    raise err
  File "/usr/lib/python3.6/socket.py", line 713, in create_connection
    sock.connect(sa)
ConnectionRefusedError: [Errno 111] Connection refused

During handling of the above exception, another exception occurred:

Traceback (most recent call last):
  File "/home/frappe/frappe-bench/apps/frappe/frappe/utils/scheduler.py", line 81, in enqueue_events_for_site
    if is_scheduler_inactive():
  File "/home/frappe/frappe-bench/apps/frappe/frappe/utils/scheduler.py", line 228, in is_scheduler_inactive
    if is_scheduler_disabled():
  File "/home/frappe/frappe-bench/apps/frappe/frappe/utils/scheduler.py", line 237, in is_scheduler_disabled
    return not frappe.utils.cint(frappe.db.get_single_value("System Settings", "enable_scheduler"))
  File "/home/frappe/frappe-bench/apps/frappe/frappe/database/database.py", line 553, in get_single_value
    `tabSingles` where `doctype`=%s and `field`=%s""", (doctype, fieldname))
  File "/home/frappe/frappe-bench/apps/frappe/frappe/database/database.py", line 122, in sql
    self.connect()
  File "/home/frappe/frappe-bench/apps/frappe/frappe/database/database.py", line 75, in connect
    self._conn = self.get_connection()
  File "/home/frappe/frappe-bench/apps/frappe/frappe/database/mariadb/database.py", line 90, in get_connection
    local_infile = frappe.conf.local_infile)
  File "/home/frappe/frappe-bench/env/lib/python3.6/site-packages/pymysql/__init__.py", line 94, in Connect
    return Connection(*args, **kwargs)
  File "/home/frappe/frappe-bench/env/lib/python3.6/site-packages/pymysql/connections.py", line 325, in __init__
    self.connect()
  File "/home/frappe/frappe-bench/env/lib/python3.6/site-packages/pymysql/connections.py", line 630, in connect
    raise exc
pymysql.err.OperationalError: (2003, "Can't connect to MySQL server on 'localhost' ([Errno 111] Connection refused)")

[ERROR] 2021-03-25 12:04:26,932 | /home/frappe/frappe-bench/apps/frappe/frappe/utils/scheduler.py:
Site: site1.local
Exception in Enqueue Events for Site site1.local
Traceback (most recent call last):
  File "/home/frappe/frappe-bench/env/lib/python3.6/site-packages/pymysql/connections.py", line 583, in connect
    **kwargs)
  File "/usr/lib/python3.6/socket.py", line 724, in create_connection
    raise err
  File "/usr/lib/python3.6/socket.py", line 713, in create_connection
    sock.connect(sa)
ConnectionRefusedError: [Errno 111] Connection refused

During handling of the above exception, another exception occurred:

Traceback (most recent call last):
  File "/home/frappe/frappe-bench/apps/frappe/frappe/utils/scheduler.py", line 81, in enqueue_events_for_site
    if is_scheduler_inactive():
  File "/home/frappe/frappe-bench/apps/frappe/frappe/utils/scheduler.py", line 228, in is_scheduler_inactive
    if is_scheduler_disabled():
  File "/home/frappe/frappe-bench/apps/frappe/frappe/utils/scheduler.py", line 237, in is_scheduler_disabled
    return not frappe.utils.cint(frappe.db.get_single_value("System Settings", "enable_scheduler"))
  File "/home/frappe/frappe-bench/apps/frappe/frappe/database/database.py", line 553, in get_single_value
    `tabSingles` where `doctype`=%s and `field`=%s""", (doctype, fieldname))
  File "/home/frappe/frappe-bench/apps/frappe/frappe/database/database.py", line 122, in sql
    self.connect()
  File "/home/frappe/frappe-bench/apps/frappe/frappe/database/database.py", line 75, in connect
    self._conn = self.get_connection()
  File "/home/frappe/frappe-bench/apps/frappe/frappe/database/mariadb/database.py", line 90, in get_connection
    local_infile = frappe.conf.local_infile)
  File "/home/frappe/frappe-bench/env/lib/python3.6/site-packages/pymysql/__init__.py", line 94, in Connect
    return Connection(*args, **kwargs)
  File "/home/frappe/frappe-bench/env/lib/python3.6/site-packages/pymysql/connections.py", line 325, in __init__
    self.connect()
  File "/home/frappe/frappe-bench/env/lib/python3.6/site-packages/pymysql/connections.py", line 630, in connect
    raise exc
pymysql.err.OperationalError: (2003, "Can't connect to MySQL server on 'localhost' ([Errno 111] Connection refused)")

[ERROR] 2021-03-25 12:05:27,300 | /home/frappe/frappe-bench/apps/frappe/frappe/utils/scheduler.py:
Site: site1.local
Exception in Enqueue Events for Site site1.local
Traceback (most recent call last):
  File "/home/frappe/frappe-bench/env/lib/python3.6/site-packages/pymysql/connections.py", line 583, in connect
    **kwargs)
  File "/usr/lib/python3.6/socket.py", line 724, in create_connection
    raise err
  File "/usr/lib/python3.6/socket.py", line 713, in create_connection
    sock.connect(sa)
ConnectionRefusedError: [Errno 111] Connection refused

During handling of the above exception, another exception occurred:

Traceback (most recent call last):
  File "/home/frappe/frappe-bench/apps/frappe/frappe/utils/scheduler.py", line 81, in enqueue_events_for_site
    if is_scheduler_inactive():
  File "/home/frappe/frappe-bench/apps/frappe/frappe/utils/scheduler.py", line 228, in is_scheduler_inactive
    if is_scheduler_disabled():
  File "/home/frappe/frappe-bench/apps/frappe/frappe/utils/scheduler.py", line 237, in is_scheduler_disabled
    return not frappe.utils.cint(frappe.db.get_single_value("System Settings", "enable_scheduler"))
  File "/home/frappe/frappe-bench/apps/frappe/frappe/database/database.py", line 553, in get_single_value
    `tabSingles` where `doctype`=%s and `field`=%s""", (doctype, fieldname))
  File "/home/frappe/frappe-bench/apps/frappe/frappe/database/database.py", line 122, in sql
    self.connect()
  File "/home/frappe/frappe-bench/apps/frappe/frappe/database/database.py", line 75, in connect
    self._conn = self.get_connection()
  File "/home/frappe/frappe-bench/apps/frappe/frappe/database/mariadb/database.py", line 90, in get_connection
    local_infile = frappe.conf.local_infile)
  File "/home/frappe/frappe-bench/env/lib/python3.6/site-packages/pymysql/__init__.py", line 94, in Connect
    return Connection(*args, **kwargs)
  File "/home/frappe/frappe-bench/env/lib/python3.6/site-packages/pymysql/connections.py", line 325, in __init__
    self.connect()
  File "/home/frappe/frappe-bench/env/lib/python3.6/site-packages/pymysql/connections.py", line 630, in connect
    raise exc
pymysql.err.OperationalError: (2003, "Can't connect to MySQL server on 'localhost' ([Errno 111] Connection refused)")

[ERROR] 2021-03-25 12:06:27,592 | /home/frappe/frappe-bench/apps/frappe/frappe/utils/scheduler.py:
Site: site1.local
Exception in Enqueue Events for Site site1.local
Traceback (most recent call last):
  File "/home/frappe/frappe-bench/env/lib/python3.6/site-packages/pymysql/connections.py", line 583, in connect
    **kwargs)
  File "/usr/lib/python3.6/socket.py", line 724, in create_connection
    raise err
  File "/usr/lib/python3.6/socket.py", line 713, in create_connection
    sock.connect(sa)
ConnectionRefusedError: [Errno 111] Connection refused

During handling of the above exception, another exception occurred:

Traceback (most recent call last):
  File "/home/frappe/frappe-bench/apps/frappe/frappe/utils/scheduler.py", line 81, in enqueue_events_for_site
    if is_scheduler_inactive():
  File "/home/frappe/frappe-bench/apps/frappe/frappe/utils/scheduler.py", line 228, in is_scheduler_inactive
    if is_scheduler_disabled():
  File "/home/frappe/frappe-bench/apps/frappe/frappe/utils/scheduler.py", line 237, in is_scheduler_disabled
    return not frappe.utils.cint(frappe.db.get_single_value("System Settings", "enable_scheduler"))
  File "/home/frappe/frappe-bench/apps/frappe/frappe/database/database.py", line 553, in get_single_value
    `tabSingles` where `doctype`=%s and `field`=%s""", (doctype, fieldname))
  File "/home/frappe/frappe-bench/apps/frappe/frappe/database/database.py", line 122, in sql
    self.connect()
  File "/home/frappe/frappe-bench/apps/frappe/frappe/database/database.py", line 75, in connect
    self._conn = self.get_connection()
  File "/home/frappe/frappe-bench/apps/frappe/frappe/database/mariadb/database.py", line 90, in get_connection
    local_infile = frappe.conf.local_infile)
  File "/home/frappe/frappe-bench/env/lib/python3.6/site-packages/pymysql/__init__.py", line 94, in Connect
    return Connection(*args, **kwargs)
  File "/home/frappe/frappe-bench/env/lib/python3.6/site-packages/pymysql/connections.py", line 325, in __init__
    self.connect()
  File "/home/frappe/frappe-bench/env/lib/python3.6/site-packages/pymysql/connections.py", line 630, in connect
    raise exc
pymysql.err.OperationalError: (2003, "Can't connect to MySQL server on 'localhost' ([Errno 111] Connection refused)")

[ERROR] 2021-03-25 12:07:28,016 | /home/frappe/frappe-bench/apps/frappe/frappe/utils/scheduler.py:
Site: site1.local
Exception in Enqueue Events for Site site1.local
Traceback (most recent call last):
  File "/home/frappe/frappe-bench/env/lib/python3.6/site-packages/pymysql/connections.py", line 583, in connect
    **kwargs)
  File "/usr/lib/python3.6/socket.py", line 724, in create_connection
    raise err
  File "/usr/lib/python3.6/socket.py", line 713, in create_connection
    sock.connect(sa)
ConnectionRefusedError: [Errno 111] Connection refused

During handling of the above exception, another exception occurred:

Traceback (most recent call last):
  File "/home/frappe/frappe-bench/apps/frappe/frappe/utils/scheduler.py", line 81, in enqueue_events_for_site
    if is_scheduler_inactive():
  File "/home/frappe/frappe-bench/apps/frappe/frappe/utils/scheduler.py", line 228, in is_scheduler_inactive
    if is_scheduler_disabled():
  File "/home/frappe/frappe-bench/apps/frappe/frappe/utils/scheduler.py", line 237, in is_scheduler_disabled
    return not frappe.utils.cint(frappe.db.get_single_value("System Settings", "enable_scheduler"))
  File "/home/frappe/frappe-bench/apps/frappe/frappe/database/database.py", line 553, in get_single_value
    `tabSingles` where `doctype`=%s and `field`=%s""", (doctype, fieldname))
  File "/home/frappe/frappe-bench/apps/frappe/frappe/database/database.py", line 122, in sql
    self.connect()
  File "/home/frappe/frappe-bench/apps/frappe/frappe/database/database.py", line 75, in connect
    self._conn = self.get_connection()
  File "/home/frappe/frappe-bench/apps/frappe/frappe/database/mariadb/database.py", line 90, in get_connection
    local_infile = frappe.conf.local_infile)
  File "/home/frappe/frappe-bench/env/lib/python3.6/site-packages/pymysql/__init__.py", line 94, in Connect
    return Connection(*args, **kwargs)
  File "/home/frappe/frappe-bench/env/lib/python3.6/site-packages/pymysql/connections.py", line 325, in __init__
    self.connect()
  File "/home/frappe/frappe-bench/env/lib/python3.6/site-packages/pymysql/connections.py", line 630, in connect
    raise exc
pymysql.err.OperationalError: (2003, "Can't connect to MySQL server on 'localhost' ([Errno 111] Connection refused)")

[ERROR] 2021-03-25 12:08:28,286 | /home/frappe/frappe-bench/apps/frappe/frappe/utils/scheduler.py:
Site: site1.local
Exception in Enqueue Events for Site site1.local
Traceback (most recent call last):
  File "/home/frappe/frappe-bench/env/lib/python3.6/site-packages/pymysql/connections.py", line 583, in connect
    **kwargs)
  File "/usr/lib/python3.6/socket.py", line 724, in create_connection
    raise err
  File "/usr/lib/python3.6/socket.py", line 713, in create_connection
    sock.connect(sa)
ConnectionRefusedError: [Errno 111] Connection refused

During handling of the above exception, another exception occurred:

Traceback (most recent call last):
  File "/home/frappe/frappe-bench/apps/frappe/frappe/utils/scheduler.py", line 81, in enqueue_events_for_site
    if is_scheduler_inactive():
  File "/home/frappe/frappe-bench/apps/frappe/frappe/utils/scheduler.py", line 228, in is_scheduler_inactive
    if is_scheduler_disabled():
  File "/home/frappe/frappe-bench/apps/frappe/frappe/utils/scheduler.py", line 237, in is_scheduler_disabled
    return not frappe.utils.cint(frappe.db.get_single_value("System Settings", "enable_scheduler"))
  File "/home/frappe/frappe-bench/apps/frappe/frappe/database/database.py", line 553, in get_single_value
    `tabSingles` where `doctype`=%s and `field`=%s""", (doctype, fieldname))
  File "/home/frappe/frappe-bench/apps/frappe/frappe/database/database.py", line 122, in sql
    self.connect()
  File "/home/frappe/frappe-bench/apps/frappe/frappe/database/database.py", line 75, in connect
    self._conn = self.get_connection()
  File "/home/frappe/frappe-bench/apps/frappe/frappe/database/mariadb/database.py", line 90, in get_connection
    local_infile = frappe.conf.local_infile)
  File "/home/frappe/frappe-bench/env/lib/python3.6/site-packages/pymysql/__init__.py", line 94, in Connect
    return Connection(*args, **kwargs)
  File "/home/frappe/frappe-bench/env/lib/python3.6/site-packages/pymysql/connections.py", line 325, in __init__
    self.connect()
  File "/home/frappe/frappe-bench/env/lib/python3.6/site-packages/pymysql/connections.py", line 630, in connect
    raise exc
pymysql.err.OperationalError: (2003, "Can't connect to MySQL server on 'localhost' ([Errno 111] Connection refused)")

[ERROR] 2021-03-25 12:09:28,613 | /home/frappe/frappe-bench/apps/frappe/frappe/utils/scheduler.py:
Site: site1.local
Exception in Enqueue Events for Site site1.local
Traceback (most recent call last):
  File "/home/frappe/frappe-bench/env/lib/python3.6/site-packages/pymysql/connections.py", line 583, in connect
    **kwargs)
  File "/usr/lib/python3.6/socket.py", line 724, in create_connection
    raise err
  File "/usr/lib/python3.6/socket.py", line 713, in create_connection
    sock.connect(sa)
ConnectionRefusedError: [Errno 111] Connection refused

During handling of the above exception, another exception occurred:

Traceback (most recent call last):
  File "/home/frappe/frappe-bench/apps/frappe/frappe/utils/scheduler.py", line 81, in enqueue_events_for_site
    if is_scheduler_inactive():
  File "/home/frappe/frappe-bench/apps/frappe/frappe/utils/scheduler.py", line 228, in is_scheduler_inactive
    if is_scheduler_disabled():
  File "/home/frappe/frappe-bench/apps/frappe/frappe/utils/scheduler.py", line 237, in is_scheduler_disabled
    return not frappe.utils.cint(frappe.db.get_single_value("System Settings", "enable_scheduler"))
  File "/home/frappe/frappe-bench/apps/frappe/frappe/database/database.py", line 553, in get_single_value
    `tabSingles` where `doctype`=%s and `field`=%s""", (doctype, fieldname))
  File "/home/frappe/frappe-bench/apps/frappe/frappe/database/database.py", line 122, in sql
    self.connect()
  File "/home/frappe/frappe-bench/apps/frappe/frappe/database/database.py", line 75, in connect
    self._conn = self.get_connection()
  File "/home/frappe/frappe-bench/apps/frappe/frappe/database/mariadb/database.py", line 90, in get_connection
    local_infile = frappe.conf.local_infile)
  File "/home/frappe/frappe-bench/env/lib/python3.6/site-packages/pymysql/__init__.py", line 94, in Connect
    return Connection(*args, **kwargs)
  File "/home/frappe/frappe-bench/env/lib/python3.6/site-packages/pymysql/connections.py", line 325, in __init__
    self.connect()
  File "/home/frappe/frappe-bench/env/lib/python3.6/site-packages/pymysql/connections.py", line 630, in connect
    raise exc
pymysql.err.OperationalError: (2003, "Can't connect to MySQL server on 'localhost' ([Errno 111] Connection refused)")

[ERROR] 2021-03-25 12:10:28,872 | /home/frappe/frappe-bench/apps/frappe/frappe/utils/scheduler.py:
Site: site1.local
Exception in Enqueue Events for Site site1.local
Traceback (most recent call last):
  File "/home/frappe/frappe-bench/env/lib/python3.6/site-packages/pymysql/connections.py", line 583, in connect
    **kwargs)
  File "/usr/lib/python3.6/socket.py", line 724, in create_connection
    raise err
  File "/usr/lib/python3.6/socket.py", line 713, in create_connection
    sock.connect(sa)
ConnectionRefusedError: [Errno 111] Connection refused

During handling of the above exception, another exception occurred:

Traceback (most recent call last):
  File "/home/frappe/frappe-bench/apps/frappe/frappe/utils/scheduler.py", line 81, in enqueue_events_for_site
    if is_scheduler_inactive():
  File "/home/frappe/frappe-bench/apps/frappe/frappe/utils/scheduler.py", line 228, in is_scheduler_inactive
    if is_scheduler_disabled():
  File "/home/frappe/frappe-bench/apps/frappe/frappe/utils/scheduler.py", line 237, in is_scheduler_disabled
    return not frappe.utils.cint(frappe.db.get_single_value("System Settings", "enable_scheduler"))
  File "/home/frappe/frappe-bench/apps/frappe/frappe/database/database.py", line 553, in get_single_value
    `tabSingles` where `doctype`=%s and `field`=%s""", (doctype, fieldname))
  File "/home/frappe/frappe-bench/apps/frappe/frappe/database/database.py", line 122, in sql
    self.connect()
  File "/home/frappe/frappe-bench/apps/frappe/frappe/database/database.py", line 75, in connect
    self._conn = self.get_connection()
  File "/home/frappe/frappe-bench/apps/frappe/frappe/database/mariadb/database.py", line 90, in get_connection
    local_infile = frappe.conf.local_infile)
  File "/home/frappe/frappe-bench/env/lib/python3.6/site-packages/pymysql/__init__.py", line 94, in Connect
    return Connection(*args, **kwargs)
  File "/home/frappe/frappe-bench/env/lib/python3.6/site-packages/pymysql/connections.py", line 325, in __init__
    self.connect()
  File "/home/frappe/frappe-bench/env/lib/python3.6/site-packages/pymysql/connections.py", line 630, in connect
    raise exc
pymysql.err.OperationalError: (2003, "Can't connect to MySQL server on 'localhost' ([Errno 111] Connection refused)")

[ERROR] 2021-03-25 12:11:29,136 | /home/frappe/frappe-bench/apps/frappe/frappe/utils/scheduler.py:
Site: site1.local
Exception in Enqueue Events for Site site1.local
Traceback (most recent call last):
  File "/home/frappe/frappe-bench/env/lib/python3.6/site-packages/pymysql/connections.py", line 583, in connect
    **kwargs)
  File "/usr/lib/python3.6/socket.py", line 724, in create_connection
    raise err
  File "/usr/lib/python3.6/socket.py", line 713, in create_connection
    sock.connect(sa)
ConnectionRefusedError: [Errno 111] Connection refused

During handling of the above exception, another exception occurred:

Traceback (most recent call last):
  File "/home/frappe/frappe-bench/apps/frappe/frappe/utils/scheduler.py", line 81, in enqueue_events_for_site
    if is_scheduler_inactive():
  File "/home/frappe/frappe-bench/apps/frappe/frappe/utils/scheduler.py", line 228, in is_scheduler_inactive
    if is_scheduler_disabled():
  File "/home/frappe/frappe-bench/apps/frappe/frappe/utils/scheduler.py", line 237, in is_scheduler_disabled
    return not frappe.utils.cint(frappe.db.get_single_value("System Settings", "enable_scheduler"))
  File "/home/frappe/frappe-bench/apps/frappe/frappe/database/database.py", line 553, in get_single_value
    `tabSingles` where `doctype`=%s and `field`=%s""", (doctype, fieldname))
  File "/home/frappe/frappe-bench/apps/frappe/frappe/database/database.py", line 122, in sql
    self.connect()
  File "/home/frappe/frappe-bench/apps/frappe/frappe/database/database.py", line 75, in connect
    self._conn = self.get_connection()
  File "/home/frappe/frappe-bench/apps/frappe/frappe/database/mariadb/database.py", line 90, in get_connection
    local_infile = frappe.conf.local_infile)
  File "/home/frappe/frappe-bench/env/lib/python3.6/site-packages/pymysql/__init__.py", line 94, in Connect
    return Connection(*args, **kwargs)
  File "/home/frappe/frappe-bench/env/lib/python3.6/site-packages/pymysql/connections.py", line 325, in __init__
    self.connect()
  File "/home/frappe/frappe-bench/env/lib/python3.6/site-packages/pymysql/connections.py", line 630, in connect
    raise exc
pymysql.err.OperationalError: (2003, "Can't connect to MySQL server on 'localhost' ([Errno 111] Connection refused)")

[ERROR] 2021-03-25 12:12:29,347 | /home/frappe/frappe-bench/apps/frappe/frappe/utils/scheduler.py:
Site: site1.local
Exception in Enqueue Events for Site site1.local
Traceback (most recent call last):
  File "/home/frappe/frappe-bench/env/lib/python3.6/site-packages/pymysql/connections.py", line 583, in connect
    **kwargs)
  File "/usr/lib/python3.6/socket.py", line 724, in create_connection
    raise err
  File "/usr/lib/python3.6/socket.py", line 713, in create_connection
    sock.connect(sa)
ConnectionRefusedError: [Errno 111] Connection refused

During handling of the above exception, another exception occurred:

Traceback (most recent call last):
  File "/home/frappe/frappe-bench/apps/frappe/frappe/utils/scheduler.py", line 81, in enqueue_events_for_site
    if is_scheduler_inactive():
  File "/home/frappe/frappe-bench/apps/frappe/frappe/utils/scheduler.py", line 228, in is_scheduler_inactive
    if is_scheduler_disabled():
  File "/home/frappe/frappe-bench/apps/frappe/frappe/utils/scheduler.py", line 237, in is_scheduler_disabled
    return not frappe.utils.cint(frappe.db.get_single_value("System Settings", "enable_scheduler"))
  File "/home/frappe/frappe-bench/apps/frappe/frappe/database/database.py", line 553, in get_single_value
    `tabSingles` where `doctype`=%s and `field`=%s""", (doctype, fieldname))
  File "/home/frappe/frappe-bench/apps/frappe/frappe/database/database.py", line 122, in sql
    self.connect()
  File "/home/frappe/frappe-bench/apps/frappe/frappe/database/database.py", line 75, in connect
    self._conn = self.get_connection()
  File "/home/frappe/frappe-bench/apps/frappe/frappe/database/mariadb/database.py", line 90, in get_connection
    local_infile = frappe.conf.local_infile)
  File "/home/frappe/frappe-bench/env/lib/python3.6/site-packages/pymysql/__init__.py", line 94, in Connect
    return Connection(*args, **kwargs)
  File "/home/frappe/frappe-bench/env/lib/python3.6/site-packages/pymysql/connections.py", line 325, in __init__
    self.connect()
  File "/home/frappe/frappe-bench/env/lib/python3.6/site-packages/pymysql/connections.py", line 630, in connect
    raise exc
pymysql.err.OperationalError: (2003, "Can't connect to MySQL server on 'localhost' ([Errno 111] Connection refused)")

[ERROR] 2021-03-25 12:13:29,572 | /home/frappe/frappe-bench/apps/frappe/frappe/utils/scheduler.py:
Site: site1.local
Exception in Enqueue Events for Site site1.local
Traceback (most recent call last):
  File "/home/frappe/frappe-bench/env/lib/python3.6/site-packages/pymysql/connections.py", line 583, in connect
    **kwargs)
  File "/usr/lib/python3.6/socket.py", line 724, in create_connection
    raise err
  File "/usr/lib/python3.6/socket.py", line 713, in create_connection
    sock.connect(sa)
ConnectionRefusedError: [Errno 111] Connection refused

During handling of the above exception, another exception occurred:

Traceback (most recent call last):
  File "/home/frappe/frappe-bench/apps/frappe/frappe/utils/scheduler.py", line 81, in enqueue_events_for_site
    if is_scheduler_inactive():
  File "/home/frappe/frappe-bench/apps/frappe/frappe/utils/scheduler.py", line 228, in is_scheduler_inactive
    if is_scheduler_disabled():
  File "/home/frappe/frappe-bench/apps/frappe/frappe/utils/scheduler.py", line 237, in is_scheduler_disabled
    return not frappe.utils.cint(frappe.db.get_single_value("System Settings", "enable_scheduler"))
  File "/home/frappe/frappe-bench/apps/frappe/frappe/database/database.py", line 553, in get_single_value
    `tabSingles` where `doctype`=%s and `field`=%s""", (doctype, fieldname))
  File "/home/frappe/frappe-bench/apps/frappe/frappe/database/database.py", line 122, in sql
    self.connect()
  File "/home/frappe/frappe-bench/apps/frappe/frappe/database/database.py", line 75, in connect
    self._conn = self.get_connection()
  File "/home/frappe/frappe-bench/apps/frappe/frappe/database/mariadb/database.py", line 90, in get_connection
    local_infile = frappe.conf.local_infile)
  File "/home/frappe/frappe-bench/env/lib/python3.6/site-packages/pymysql/__init__.py", line 94, in Connect
    return Connection(*args, **kwargs)
  File "/home/frappe/frappe-bench/env/lib/python3.6/site-packages/pymysql/connections.py", line 325, in __init__
    self.connect()
  File "/home/frappe/frappe-bench/env/lib/python3.6/site-packages/pymysql/connections.py", line 630, in connect
    raise exc
pymysql.err.OperationalError: (2003, "Can't connect to MySQL server on 'localhost' ([Errno 111] Connection refused)")

[ERROR] 2021-03-25 12:14:29,871 | /home/frappe/frappe-bench/apps/frappe/frappe/utils/scheduler.py:
Site: site1.local
Exception in Enqueue Events for Site site1.local
Traceback (most recent call last):
  File "/home/frappe/frappe-bench/env/lib/python3.6/site-packages/pymysql/connections.py", line 583, in connect
    **kwargs)
  File "/usr/lib/python3.6/socket.py", line 724, in create_connection
    raise err
  File "/usr/lib/python3.6/socket.py", line 713, in create_connection
    sock.connect(sa)
ConnectionRefusedError: [Errno 111] Connection refused

During handling of the above exception, another exception occurred:

Traceback (most recent call last):
  File "/home/frappe/frappe-bench/apps/frappe/frappe/utils/scheduler.py", line 81, in enqueue_events_for_site
    if is_scheduler_inactive():
  File "/home/frappe/frappe-bench/apps/frappe/frappe/utils/scheduler.py", line 228, in is_scheduler_inactive
    if is_scheduler_disabled():
  File "/home/frappe/frappe-bench/apps/frappe/frappe/utils/scheduler.py", line 237, in is_scheduler_disabled
    return not frappe.utils.cint(frappe.db.get_single_value("System Settings", "enable_scheduler"))
  File "/home/frappe/frappe-bench/apps/frappe/frappe/database/database.py", line 553, in get_single_value
    `tabSingles` where `doctype`=%s and `field`=%s""", (doctype, fieldname))
  File "/home/frappe/frappe-bench/apps/frappe/frappe/database/database.py", line 122, in sql
    self.connect()
  File "/home/frappe/frappe-bench/apps/frappe/frappe/database/database.py", line 75, in connect
    self._conn = self.get_connection()
  File "/home/frappe/frappe-bench/apps/frappe/frappe/database/mariadb/database.py", line 90, in get_connection
    local_infile = frappe.conf.local_infile)
  File "/home/frappe/frappe-bench/env/lib/python3.6/site-packages/pymysql/__init__.py", line 94, in Connect
    return Connection(*args, **kwargs)
  File "/home/frappe/frappe-bench/env/lib/python3.6/site-packages/pymysql/connections.py", line 325, in __init__
    self.connect()
  File "/home/frappe/frappe-bench/env/lib/python3.6/site-packages/pymysql/connections.py", line 630, in connect
    raise exc
pymysql.err.OperationalError: (2003, "Can't connect to MySQL server on 'localhost' ([Errno 111] Connection refused)")

[ERROR] 2021-03-25 12:15:30,032 | /home/frappe/frappe-bench/apps/frappe/frappe/utils/scheduler.py:
Site: site1.local
Exception in Enqueue Events for Site site1.local
Traceback (most recent call last):
  File "/home/frappe/frappe-bench/env/lib/python3.6/site-packages/pymysql/connections.py", line 583, in connect
    **kwargs)
  File "/usr/lib/python3.6/socket.py", line 724, in create_connection
    raise err
  File "/usr/lib/python3.6/socket.py", line 713, in create_connection
    sock.connect(sa)
ConnectionRefusedError: [Errno 111] Connection refused

During handling of the above exception, another exception occurred:

Traceback (most recent call last):
  File "/home/frappe/frappe-bench/apps/frappe/frappe/utils/scheduler.py", line 81, in enqueue_events_for_site
    if is_scheduler_inactive():
  File "/home/frappe/frappe-bench/apps/frappe/frappe/utils/scheduler.py", line 228, in is_scheduler_inactive
    if is_scheduler_disabled():
  File "/home/frappe/frappe-bench/apps/frappe/frappe/utils/scheduler.py", line 237, in is_scheduler_disabled
    return not frappe.utils.cint(frappe.db.get_single_value("System Settings", "enable_scheduler"))
  File "/home/frappe/frappe-bench/apps/frappe/frappe/database/database.py", line 553, in get_single_value
    `tabSingles` where `doctype`=%s and `field`=%s""", (doctype, fieldname))
  File "/home/frappe/frappe-bench/apps/frappe/frappe/database/database.py", line 122, in sql
    self.connect()
  File "/home/frappe/frappe-bench/apps/frappe/frappe/database/database.py", line 75, in connect
    self._conn = self.get_connection()
  File "/home/frappe/frappe-bench/apps/frappe/frappe/database/mariadb/database.py", line 90, in get_connection
    local_infile = frappe.conf.local_infile)
  File "/home/frappe/frappe-bench/env/lib/python3.6/site-packages/pymysql/__init__.py", line 94, in Connect
    return Connection(*args, **kwargs)
  File "/home/frappe/frappe-bench/env/lib/python3.6/site-packages/pymysql/connections.py", line 325, in __init__
    self.connect()
  File "/home/frappe/frappe-bench/env/lib/python3.6/site-packages/pymysql/connections.py", line 630, in connect
    raise exc
pymysql.err.OperationalError: (2003, "Can't connect to MySQL server on 'localhost' ([Errno 111] Connection refused)")

[ERROR] 2021-03-25 12:16:30,315 | /home/frappe/frappe-bench/apps/frappe/frappe/utils/scheduler.py:
Site: site1.local
Exception in Enqueue Events for Site site1.local
Traceback (most recent call last):
  File "/home/frappe/frappe-bench/env/lib/python3.6/site-packages/pymysql/connections.py", line 583, in connect
    **kwargs)
  File "/usr/lib/python3.6/socket.py", line 724, in create_connection
    raise err
  File "/usr/lib/python3.6/socket.py", line 713, in create_connection
    sock.connect(sa)
ConnectionRefusedError: [Errno 111] Connection refused

During handling of the above exception, another exception occurred:

Traceback (most recent call last):
  File "/home/frappe/frappe-bench/apps/frappe/frappe/utils/scheduler.py", line 81, in enqueue_events_for_site
    if is_scheduler_inactive():
  File "/home/frappe/frappe-bench/apps/frappe/frappe/utils/scheduler.py", line 228, in is_scheduler_inactive
    if is_scheduler_disabled():
  File "/home/frappe/frappe-bench/apps/frappe/frappe/utils/scheduler.py", line 237, in is_scheduler_disabled
    return not frappe.utils.cint(frappe.db.get_single_value("System Settings", "enable_scheduler"))
  File "/home/frappe/frappe-bench/apps/frappe/frappe/database/database.py", line 553, in get_single_value
    `tabSingles` where `doctype`=%s and `field`=%s""", (doctype, fieldname))
  File "/home/frappe/frappe-bench/apps/frappe/frappe/database/database.py", line 122, in sql
    self.connect()
  File "/home/frappe/frappe-bench/apps/frappe/frappe/database/database.py", line 75, in connect
    self._conn = self.get_connection()
  File "/home/frappe/frappe-bench/apps/frappe/frappe/database/mariadb/database.py", line 90, in get_connection
    local_infile = frappe.conf.local_infile)
  File "/home/frappe/frappe-bench/env/lib/python3.6/site-packages/pymysql/__init__.py", line 94, in Connect
    return Connection(*args, **kwargs)
  File "/home/frappe/frappe-bench/env/lib/python3.6/site-packages/pymysql/connections.py", line 325, in __init__
    self.connect()
  File "/home/frappe/frappe-bench/env/lib/python3.6/site-packages/pymysql/connections.py", line 630, in connect
    raise exc
pymysql.err.OperationalError: (2003, "Can't connect to MySQL server on 'localhost' ([Errno 111] Connection refused)")

[ERROR] 2021-03-25 12:17:30,515 | /home/frappe/frappe-bench/apps/frappe/frappe/utils/scheduler.py:
Site: site1.local
Exception in Enqueue Events for Site site1.local
Traceback (most recent call last):
  File "/home/frappe/frappe-bench/env/lib/python3.6/site-packages/pymysql/connections.py", line 583, in connect
    **kwargs)
  File "/usr/lib/python3.6/socket.py", line 724, in create_connection
    raise err
  File "/usr/lib/python3.6/socket.py", line 713, in create_connection
    sock.connect(sa)
ConnectionRefusedError: [Errno 111] Connection refused

During handling of the above exception, another exception occurred:

Traceback (most recent call last):
  File "/home/frappe/frappe-bench/apps/frappe/frappe/utils/scheduler.py", line 81, in enqueue_events_for_site
    if is_scheduler_inactive():
  File "/home/frappe/frappe-bench/apps/frappe/frappe/utils/scheduler.py", line 228, in is_scheduler_inactive
    if is_scheduler_disabled():
  File "/home/frappe/frappe-bench/apps/frappe/frappe/utils/scheduler.py", line 237, in is_scheduler_disabled
    return not frappe.utils.cint(frappe.db.get_single_value("System Settings", "enable_scheduler"))
  File "/home/frappe/frappe-bench/apps/frappe/frappe/database/database.py", line 553, in get_single_value
    `tabSingles` where `doctype`=%s and `field`=%s""", (doctype, fieldname))
  File "/home/frappe/frappe-bench/apps/frappe/frappe/database/database.py", line 122, in sql
    self.connect()
  File "/home/frappe/frappe-bench/apps/frappe/frappe/database/database.py", line 75, in connect
    self._conn = self.get_connection()
  File "/home/frappe/frappe-bench/apps/frappe/frappe/database/mariadb/database.py", line 90, in get_connection
    local_infile = frappe.conf.local_infile)
  File "/home/frappe/frappe-bench/env/lib/python3.6/site-packages/pymysql/__init__.py", line 94, in Connect
    return Connection(*args, **kwargs)
  File "/home/frappe/frappe-bench/env/lib/python3.6/site-packages/pymysql/connections.py", line 325, in __init__
    self.connect()
  File "/home/frappe/frappe-bench/env/lib/python3.6/site-packages/pymysql/connections.py", line 630, in connect
    raise exc
pymysql.err.OperationalError: (2003, "Can't connect to MySQL server on 'localhost' ([Errno 111] Connection refused)")

[ERROR] 2021-03-25 12:18:30,671 | /home/frappe/frappe-bench/apps/frappe/frappe/utils/scheduler.py:
Site: site1.local
Exception in Enqueue Events for Site site1.local
Traceback (most recent call last):
  File "/home/frappe/frappe-bench/env/lib/python3.6/site-packages/pymysql/connections.py", line 583, in connect
    **kwargs)
  File "/usr/lib/python3.6/socket.py", line 724, in create_connection
    raise err
  File "/usr/lib/python3.6/socket.py", line 713, in create_connection
    sock.connect(sa)
ConnectionRefusedError: [Errno 111] Connection refused

During handling of the above exception, another exception occurred:

Traceback (most recent call last):
  File "/home/frappe/frappe-bench/apps/frappe/frappe/utils/scheduler.py", line 81, in enqueue_events_for_site
    if is_scheduler_inactive():
  File "/home/frappe/frappe-bench/apps/frappe/frappe/utils/scheduler.py", line 228, in is_scheduler_inactive
    if is_scheduler_disabled():
  File "/home/frappe/frappe-bench/apps/frappe/frappe/utils/scheduler.py", line 237, in is_scheduler_disabled
    return not frappe.utils.cint(frappe.db.get_single_value("System Settings", "enable_scheduler"))
  File "/home/frappe/frappe-bench/apps/frappe/frappe/database/database.py", line 553, in get_single_value
    `tabSingles` where `doctype`=%s and `field`=%s""", (doctype, fieldname))
  File "/home/frappe/frappe-bench/apps/frappe/frappe/database/database.py", line 122, in sql
    self.connect()
  File "/home/frappe/frappe-bench/apps/frappe/frappe/database/database.py", line 75, in connect
    self._conn = self.get_connection()
  File "/home/frappe/frappe-bench/apps/frappe/frappe/database/mariadb/database.py", line 90, in get_connection
    local_infile = frappe.conf.local_infile)
  File "/home/frappe/frappe-bench/env/lib/python3.6/site-packages/pymysql/__init__.py", line 94, in Connect
    return Connection(*args, **kwargs)
  File "/home/frappe/frappe-bench/env/lib/python3.6/site-packages/pymysql/connections.py", line 325, in __init__
    self.connect()
  File "/home/frappe/frappe-bench/env/lib/python3.6/site-packages/pymysql/connections.py", line 630, in connect
    raise exc
pymysql.err.OperationalError: (2003, "Can't connect to MySQL server on 'localhost' ([Errno 111] Connection refused)")

[ERROR] 2021-03-25 12:19:30,996 | /home/frappe/frappe-bench/apps/frappe/frappe/utils/scheduler.py:
Site: site1.local
Exception in Enqueue Events for Site site1.local
Traceback (most recent call last):
  File "/home/frappe/frappe-bench/env/lib/python3.6/site-packages/pymysql/connections.py", line 583, in connect
    **kwargs)
  File "/usr/lib/python3.6/socket.py", line 724, in create_connection
    raise err
  File "/usr/lib/python3.6/socket.py", line 713, in create_connection
    sock.connect(sa)
ConnectionRefusedError: [Errno 111] Connection refused

During handling of the above exception, another exception occurred:

Traceback (most recent call last):
  File "/home/frappe/frappe-bench/apps/frappe/frappe/utils/scheduler.py", line 81, in enqueue_events_for_site
    if is_scheduler_inactive():
  File "/home/frappe/frappe-bench/apps/frappe/frappe/utils/scheduler.py", line 228, in is_scheduler_inactive
    if is_scheduler_disabled():
  File "/home/frappe/frappe-bench/apps/frappe/frappe/utils/scheduler.py", line 237, in is_scheduler_disabled
    return not frappe.utils.cint(frappe.db.get_single_value("System Settings", "enable_scheduler"))
  File "/home/frappe/frappe-bench/apps/frappe/frappe/database/database.py", line 553, in get_single_value
    `tabSingles` where `doctype`=%s and `field`=%s""", (doctype, fieldname))
  File "/home/frappe/frappe-bench/apps/frappe/frappe/database/database.py", line 122, in sql
    self.connect()
  File "/home/frappe/frappe-bench/apps/frappe/frappe/database/database.py", line 75, in connect
    self._conn = self.get_connection()
  File "/home/frappe/frappe-bench/apps/frappe/frappe/database/mariadb/database.py", line 90, in get_connection
    local_infile = frappe.conf.local_infile)
  File "/home/frappe/frappe-bench/env/lib/python3.6/site-packages/pymysql/__init__.py", line 94, in Connect
    return Connection(*args, **kwargs)
  File "/home/frappe/frappe-bench/env/lib/python3.6/site-packages/pymysql/connections.py", line 325, in __init__
    self.connect()
  File "/home/frappe/frappe-bench/env/lib/python3.6/site-packages/pymysql/connections.py", line 630, in connect
    raise exc
pymysql.err.OperationalError: (2003, "Can't connect to MySQL server on 'localhost' ([Errno 111] Connection refused)")

[DEBUG] 2021-03-25 12:20:31,469 | /home/frappe/frappe-bench/apps/frappe/frappe/utils/scheduler.py:
Site: site1.local
Queued events for site site1.local
[DEBUG] 2021-03-25 12:21:31,619 | /home/frappe/frappe-bench/apps/frappe/frappe/utils/scheduler.py:
Site: site1.local
Queued events for site site1.local
[DEBUG] 2021-03-25 12:22:32,041 | /home/frappe/frappe-bench/apps/frappe/frappe/utils/scheduler.py:
Site: site1.local
Queued events for site site1.local
[DEBUG] 2021-03-25 12:23:32,256 | /home/frappe/frappe-bench/apps/frappe/frappe/utils/scheduler.py:
Site: site1.local
Queued events for site site1.local
[DEBUG] 2021-03-25 12:24:32,584 | /home/frappe/frappe-bench/apps/frappe/frappe/utils/scheduler.py:
Site: site1.local
Queued events for site site1.local
[DEBUG] 2021-03-25 12:25:32,790 | /home/frappe/frappe-bench/apps/frappe/frappe/utils/scheduler.py:
Site: site1.local
Queued events for site site1.local
[DEBUG] 2021-03-25 12:26:33,000 | /home/frappe/frappe-bench/apps/frappe/frappe/utils/scheduler.py:
Site: site1.local
Queued events for site site1.local
[DEBUG] 2021-03-25 12:27:33,240 | /home/frappe/frappe-bench/apps/frappe/frappe/utils/scheduler.py:
Site: site1.local
Queued events for site site1.local
[DEBUG] 2021-03-25 12:28:33,493 | /home/frappe/frappe-bench/apps/frappe/frappe/utils/scheduler.py:
Site: site1.local
Queued events for site site1.local
[DEBUG] 2021-03-25 12:29:33,694 | /home/frappe/frappe-bench/apps/frappe/frappe/utils/scheduler.py:
Site: site1.local
Queued events for site site1.local
[DEBUG] 2021-03-25 12:30:33,971 | /home/frappe/frappe-bench/apps/frappe/frappe/utils/scheduler.py:
Site: site1.local
Queued events for site site1.local
[DEBUG] 2021-03-25 12:31:34,293 | /home/frappe/frappe-bench/apps/frappe/frappe/utils/scheduler.py:
Site: site1.local
Queued events for site site1.local
[DEBUG] 2021-03-25 12:32:34,462 | /home/frappe/frappe-bench/apps/frappe/frappe/utils/scheduler.py:
Site: site1.local
Queued events for site site1.local
[DEBUG] 2021-03-25 12:33:34,656 | /home/frappe/frappe-bench/apps/frappe/frappe/utils/scheduler.py:
Site: site1.local
Queued events for site site1.local
                                                                                                                                                        